{
 "cells": [
  {
   "cell_type": "code",
   "execution_count": 1,
   "metadata": {},
   "outputs": [
    {
     "name": "stdout",
     "output_type": "stream",
     "text": [
      "/Users/seungmin/Projects/OpenVINO/tensorflow-yolo-v3\n"
     ]
    }
   ],
   "source": [
    "%cd path/to/your/project"
   ]
  },
  {
   "cell_type": "code",
   "execution_count": 5,
   "metadata": {},
   "outputs": [
    {
     "name": "stdout",
     "output_type": "stream",
     "text": [
      "Downloading coco.names\n",
      " 1311% \n",
      "Downloading yolov3.weights\n",
      "  100% \n"
     ]
    }
   ],
   "source": [
    "# Download weights for vanilla YOLOv3\n",
    "!wget -c https://pjreddie.com/media/files/yolov3.weights"
   ]
  },
  {
   "cell_type": "code",
   "execution_count": 13,
   "metadata": {},
   "outputs": [
    {
     "name": "stdout",
     "output_type": "stream",
     "text": [
      "WARNING:tensorflow:\n",
      "The TensorFlow contrib module will not be included in TensorFlow 2.0.\n",
      "For more information, please see:\n",
      "  * https://github.com/tensorflow/community/blob/master/rfcs/20180907-contrib-sunset.md\n",
      "  * https://github.com/tensorflow/addons\n",
      "  * https://github.com/tensorflow/io (for I/O related ops)\n",
      "If you depend on functionality not listed there, please file an issue.\n",
      "\n",
      "WARNING:tensorflow:From convert_weights_pb.py:56: The name tf.app.run is deprecated. Please use tf.compat.v1.app.run instead.\n",
      "\n",
      "WARNING:tensorflow:From convert_weights_pb.py:42: The name tf.placeholder is deprecated. Please use tf.compat.v1.placeholder instead.\n",
      "\n",
      "W0925 10:35:13.316523 4643411392 deprecation_wrapper.py:119] From convert_weights_pb.py:42: The name tf.placeholder is deprecated. Please use tf.compat.v1.placeholder instead.\n",
      "\n",
      "WARNING:tensorflow:From convert_weights_pb.py:44: The name tf.variable_scope is deprecated. Please use tf.compat.v1.variable_scope instead.\n",
      "\n",
      "W0925 10:35:13.318420 4643411392 deprecation_wrapper.py:119] From convert_weights_pb.py:44: The name tf.variable_scope is deprecated. Please use tf.compat.v1.variable_scope instead.\n",
      "\n",
      "WARNING:tensorflow:Entity <bound method Conv.call of <tensorflow.python.layers.convolutional.Conv2D object at 0x1372453c8>> could not be transformed and will be executed as-is. Please report this to the AutgoGraph team. When filing the bug, set the verbosity to 10 (on Linux, `export AUTOGRAPH_VERBOSITY=10`) and attach the full output. Cause: converting <bound method Conv.call of <tensorflow.python.layers.convolutional.Conv2D object at 0x1372453c8>>: AssertionError: Bad argument number for Name: 3, expecting 4\n",
      "W0925 10:35:13.397093 4643411392 ag_logging.py:145] Entity <bound method Conv.call of <tensorflow.python.layers.convolutional.Conv2D object at 0x1372453c8>> could not be transformed and will be executed as-is. Please report this to the AutgoGraph team. When filing the bug, set the verbosity to 10 (on Linux, `export AUTOGRAPH_VERBOSITY=10`) and attach the full output. Cause: converting <bound method Conv.call of <tensorflow.python.layers.convolutional.Conv2D object at 0x1372453c8>>: AssertionError: Bad argument number for Name: 3, expecting 4\n",
      "WARNING:tensorflow:Entity <bound method BatchNormalization.call of <tensorflow.python.layers.normalization.BatchNormalization object at 0x137245da0>> could not be transformed and will be executed as-is. Please report this to the AutgoGraph team. When filing the bug, set the verbosity to 10 (on Linux, `export AUTOGRAPH_VERBOSITY=10`) and attach the full output. Cause: converting <bound method BatchNormalization.call of <tensorflow.python.layers.normalization.BatchNormalization object at 0x137245da0>>: AssertionError: Bad argument number for Name: 3, expecting 4\n",
      "W0925 10:35:13.442834 4643411392 ag_logging.py:145] Entity <bound method BatchNormalization.call of <tensorflow.python.layers.normalization.BatchNormalization object at 0x137245da0>> could not be transformed and will be executed as-is. Please report this to the AutgoGraph team. When filing the bug, set the verbosity to 10 (on Linux, `export AUTOGRAPH_VERBOSITY=10`) and attach the full output. Cause: converting <bound method BatchNormalization.call of <tensorflow.python.layers.normalization.BatchNormalization object at 0x137245da0>>: AssertionError: Bad argument number for Name: 3, expecting 4\n",
      "WARNING:tensorflow:Entity <bound method Conv.call of <tensorflow.python.layers.convolutional.Conv2D object at 0x137245a20>> could not be transformed and will be executed as-is. Please report this to the AutgoGraph team. When filing the bug, set the verbosity to 10 (on Linux, `export AUTOGRAPH_VERBOSITY=10`) and attach the full output. Cause: converting <bound method Conv.call of <tensorflow.python.layers.convolutional.Conv2D object at 0x137245a20>>: AssertionError: Bad argument number for Name: 3, expecting 4\n",
      "W0925 10:35:13.544550 4643411392 ag_logging.py:145] Entity <bound method Conv.call of <tensorflow.python.layers.convolutional.Conv2D object at 0x137245a20>> could not be transformed and will be executed as-is. Please report this to the AutgoGraph team. When filing the bug, set the verbosity to 10 (on Linux, `export AUTOGRAPH_VERBOSITY=10`) and attach the full output. Cause: converting <bound method Conv.call of <tensorflow.python.layers.convolutional.Conv2D object at 0x137245a20>>: AssertionError: Bad argument number for Name: 3, expecting 4\n",
      "WARNING:tensorflow:Entity <bound method BatchNormalization.call of <tensorflow.python.layers.normalization.BatchNormalization object at 0x1265be2e8>> could not be transformed and will be executed as-is. Please report this to the AutgoGraph team. When filing the bug, set the verbosity to 10 (on Linux, `export AUTOGRAPH_VERBOSITY=10`) and attach the full output. Cause: converting <bound method BatchNormalization.call of <tensorflow.python.layers.normalization.BatchNormalization object at 0x1265be2e8>>: AssertionError: Bad argument number for Name: 3, expecting 4\n",
      "W0925 10:35:13.587094 4643411392 ag_logging.py:145] Entity <bound method BatchNormalization.call of <tensorflow.python.layers.normalization.BatchNormalization object at 0x1265be2e8>> could not be transformed and will be executed as-is. Please report this to the AutgoGraph team. When filing the bug, set the verbosity to 10 (on Linux, `export AUTOGRAPH_VERBOSITY=10`) and attach the full output. Cause: converting <bound method BatchNormalization.call of <tensorflow.python.layers.normalization.BatchNormalization object at 0x1265be2e8>>: AssertionError: Bad argument number for Name: 3, expecting 4\n",
      "WARNING:tensorflow:Entity <bound method Conv.call of <tensorflow.python.layers.convolutional.Conv2D object at 0x1372bef60>> could not be transformed and will be executed as-is. Please report this to the AutgoGraph team. When filing the bug, set the verbosity to 10 (on Linux, `export AUTOGRAPH_VERBOSITY=10`) and attach the full output. Cause: converting <bound method Conv.call of <tensorflow.python.layers.convolutional.Conv2D object at 0x1372bef60>>: AssertionError: Bad argument number for Name: 3, expecting 4\n",
      "W0925 10:35:13.675440 4643411392 ag_logging.py:145] Entity <bound method Conv.call of <tensorflow.python.layers.convolutional.Conv2D object at 0x1372bef60>> could not be transformed and will be executed as-is. Please report this to the AutgoGraph team. When filing the bug, set the verbosity to 10 (on Linux, `export AUTOGRAPH_VERBOSITY=10`) and attach the full output. Cause: converting <bound method Conv.call of <tensorflow.python.layers.convolutional.Conv2D object at 0x1372bef60>>: AssertionError: Bad argument number for Name: 3, expecting 4\n",
      "WARNING:tensorflow:Entity <bound method BatchNormalization.call of <tensorflow.python.layers.normalization.BatchNormalization object at 0x1372670b8>> could not be transformed and will be executed as-is. Please report this to the AutgoGraph team. When filing the bug, set the verbosity to 10 (on Linux, `export AUTOGRAPH_VERBOSITY=10`) and attach the full output. Cause: converting <bound method BatchNormalization.call of <tensorflow.python.layers.normalization.BatchNormalization object at 0x1372670b8>>: AssertionError: Bad argument number for Name: 3, expecting 4\n",
      "W0925 10:35:13.708154 4643411392 ag_logging.py:145] Entity <bound method BatchNormalization.call of <tensorflow.python.layers.normalization.BatchNormalization object at 0x1372670b8>> could not be transformed and will be executed as-is. Please report this to the AutgoGraph team. When filing the bug, set the verbosity to 10 (on Linux, `export AUTOGRAPH_VERBOSITY=10`) and attach the full output. Cause: converting <bound method BatchNormalization.call of <tensorflow.python.layers.normalization.BatchNormalization object at 0x1372670b8>>: AssertionError: Bad argument number for Name: 3, expecting 4\n",
      "WARNING:tensorflow:Entity <bound method Conv.call of <tensorflow.python.layers.convolutional.Conv2D object at 0x1372bef28>> could not be transformed and will be executed as-is. Please report this to the AutgoGraph team. When filing the bug, set the verbosity to 10 (on Linux, `export AUTOGRAPH_VERBOSITY=10`) and attach the full output. Cause: converting <bound method Conv.call of <tensorflow.python.layers.convolutional.Conv2D object at 0x1372bef28>>: AssertionError: Bad argument number for Name: 3, expecting 4\n",
      "W0925 10:35:13.786106 4643411392 ag_logging.py:145] Entity <bound method Conv.call of <tensorflow.python.layers.convolutional.Conv2D object at 0x1372bef28>> could not be transformed and will be executed as-is. Please report this to the AutgoGraph team. When filing the bug, set the verbosity to 10 (on Linux, `export AUTOGRAPH_VERBOSITY=10`) and attach the full output. Cause: converting <bound method Conv.call of <tensorflow.python.layers.convolutional.Conv2D object at 0x1372bef28>>: AssertionError: Bad argument number for Name: 3, expecting 4\n",
      "WARNING:tensorflow:Entity <bound method BatchNormalization.call of <tensorflow.python.layers.normalization.BatchNormalization object at 0x137267198>> could not be transformed and will be executed as-is. Please report this to the AutgoGraph team. When filing the bug, set the verbosity to 10 (on Linux, `export AUTOGRAPH_VERBOSITY=10`) and attach the full output. Cause: converting <bound method BatchNormalization.call of <tensorflow.python.layers.normalization.BatchNormalization object at 0x137267198>>: AssertionError: Bad argument number for Name: 3, expecting 4\n",
      "W0925 10:35:13.814145 4643411392 ag_logging.py:145] Entity <bound method BatchNormalization.call of <tensorflow.python.layers.normalization.BatchNormalization object at 0x137267198>> could not be transformed and will be executed as-is. Please report this to the AutgoGraph team. When filing the bug, set the verbosity to 10 (on Linux, `export AUTOGRAPH_VERBOSITY=10`) and attach the full output. Cause: converting <bound method BatchNormalization.call of <tensorflow.python.layers.normalization.BatchNormalization object at 0x137267198>>: AssertionError: Bad argument number for Name: 3, expecting 4\n"
     ]
    },
    {
     "name": "stdout",
     "output_type": "stream",
     "text": [
      "WARNING:tensorflow:Entity <bound method Conv.call of <tensorflow.python.layers.convolutional.Conv2D object at 0x1372be898>> could not be transformed and will be executed as-is. Please report this to the AutgoGraph team. When filing the bug, set the verbosity to 10 (on Linux, `export AUTOGRAPH_VERBOSITY=10`) and attach the full output. Cause: converting <bound method Conv.call of <tensorflow.python.layers.convolutional.Conv2D object at 0x1372be898>>: AssertionError: Bad argument number for Name: 3, expecting 4\n",
      "W0925 10:35:13.893560 4643411392 ag_logging.py:145] Entity <bound method Conv.call of <tensorflow.python.layers.convolutional.Conv2D object at 0x1372be898>> could not be transformed and will be executed as-is. Please report this to the AutgoGraph team. When filing the bug, set the verbosity to 10 (on Linux, `export AUTOGRAPH_VERBOSITY=10`) and attach the full output. Cause: converting <bound method Conv.call of <tensorflow.python.layers.convolutional.Conv2D object at 0x1372be898>>: AssertionError: Bad argument number for Name: 3, expecting 4\n",
      "WARNING:tensorflow:Entity <bound method BatchNormalization.call of <tensorflow.python.layers.normalization.BatchNormalization object at 0x13735bcc0>> could not be transformed and will be executed as-is. Please report this to the AutgoGraph team. When filing the bug, set the verbosity to 10 (on Linux, `export AUTOGRAPH_VERBOSITY=10`) and attach the full output. Cause: converting <bound method BatchNormalization.call of <tensorflow.python.layers.normalization.BatchNormalization object at 0x13735bcc0>>: AssertionError: Bad argument number for Name: 3, expecting 4\n",
      "W0925 10:35:13.925680 4643411392 ag_logging.py:145] Entity <bound method BatchNormalization.call of <tensorflow.python.layers.normalization.BatchNormalization object at 0x13735bcc0>> could not be transformed and will be executed as-is. Please report this to the AutgoGraph team. When filing the bug, set the verbosity to 10 (on Linux, `export AUTOGRAPH_VERBOSITY=10`) and attach the full output. Cause: converting <bound method BatchNormalization.call of <tensorflow.python.layers.normalization.BatchNormalization object at 0x13735bcc0>>: AssertionError: Bad argument number for Name: 3, expecting 4\n",
      "WARNING:tensorflow:Entity <bound method Conv.call of <tensorflow.python.layers.convolutional.Conv2D object at 0x1372670b8>> could not be transformed and will be executed as-is. Please report this to the AutgoGraph team. When filing the bug, set the verbosity to 10 (on Linux, `export AUTOGRAPH_VERBOSITY=10`) and attach the full output. Cause: converting <bound method Conv.call of <tensorflow.python.layers.convolutional.Conv2D object at 0x1372670b8>>: AssertionError: Bad argument number for Name: 3, expecting 4\n",
      "W0925 10:35:14.009011 4643411392 ag_logging.py:145] Entity <bound method Conv.call of <tensorflow.python.layers.convolutional.Conv2D object at 0x1372670b8>> could not be transformed and will be executed as-is. Please report this to the AutgoGraph team. When filing the bug, set the verbosity to 10 (on Linux, `export AUTOGRAPH_VERBOSITY=10`) and attach the full output. Cause: converting <bound method Conv.call of <tensorflow.python.layers.convolutional.Conv2D object at 0x1372670b8>>: AssertionError: Bad argument number for Name: 3, expecting 4\n",
      "WARNING:tensorflow:Entity <bound method BatchNormalization.call of <tensorflow.python.layers.normalization.BatchNormalization object at 0x13737dd68>> could not be transformed and will be executed as-is. Please report this to the AutgoGraph team. When filing the bug, set the verbosity to 10 (on Linux, `export AUTOGRAPH_VERBOSITY=10`) and attach the full output. Cause: converting <bound method BatchNormalization.call of <tensorflow.python.layers.normalization.BatchNormalization object at 0x13737dd68>>: AssertionError: Bad argument number for Name: 3, expecting 4\n",
      "W0925 10:35:14.051691 4643411392 ag_logging.py:145] Entity <bound method BatchNormalization.call of <tensorflow.python.layers.normalization.BatchNormalization object at 0x13737dd68>> could not be transformed and will be executed as-is. Please report this to the AutgoGraph team. When filing the bug, set the verbosity to 10 (on Linux, `export AUTOGRAPH_VERBOSITY=10`) and attach the full output. Cause: converting <bound method BatchNormalization.call of <tensorflow.python.layers.normalization.BatchNormalization object at 0x13737dd68>>: AssertionError: Bad argument number for Name: 3, expecting 4\n",
      "WARNING:tensorflow:Entity <bound method Conv.call of <tensorflow.python.layers.convolutional.Conv2D object at 0x13735bcc0>> could not be transformed and will be executed as-is. Please report this to the AutgoGraph team. When filing the bug, set the verbosity to 10 (on Linux, `export AUTOGRAPH_VERBOSITY=10`) and attach the full output. Cause: converting <bound method Conv.call of <tensorflow.python.layers.convolutional.Conv2D object at 0x13735bcc0>>: AssertionError: Bad argument number for Name: 3, expecting 4\n",
      "W0925 10:35:14.136997 4643411392 ag_logging.py:145] Entity <bound method Conv.call of <tensorflow.python.layers.convolutional.Conv2D object at 0x13735bcc0>> could not be transformed and will be executed as-is. Please report this to the AutgoGraph team. When filing the bug, set the verbosity to 10 (on Linux, `export AUTOGRAPH_VERBOSITY=10`) and attach the full output. Cause: converting <bound method Conv.call of <tensorflow.python.layers.convolutional.Conv2D object at 0x13735bcc0>>: AssertionError: Bad argument number for Name: 3, expecting 4\n",
      "WARNING:tensorflow:Entity <bound method BatchNormalization.call of <tensorflow.python.layers.normalization.BatchNormalization object at 0x1372672b0>> could not be transformed and will be executed as-is. Please report this to the AutgoGraph team. When filing the bug, set the verbosity to 10 (on Linux, `export AUTOGRAPH_VERBOSITY=10`) and attach the full output. Cause: converting <bound method BatchNormalization.call of <tensorflow.python.layers.normalization.BatchNormalization object at 0x1372672b0>>: AssertionError: Bad argument number for Name: 3, expecting 4\n",
      "W0925 10:35:14.168329 4643411392 ag_logging.py:145] Entity <bound method BatchNormalization.call of <tensorflow.python.layers.normalization.BatchNormalization object at 0x1372672b0>> could not be transformed and will be executed as-is. Please report this to the AutgoGraph team. When filing the bug, set the verbosity to 10 (on Linux, `export AUTOGRAPH_VERBOSITY=10`) and attach the full output. Cause: converting <bound method BatchNormalization.call of <tensorflow.python.layers.normalization.BatchNormalization object at 0x1372672b0>>: AssertionError: Bad argument number for Name: 3, expecting 4\n",
      "WARNING:tensorflow:Entity <bound method Conv.call of <tensorflow.python.layers.convolutional.Conv2D object at 0x13735bcc0>> could not be transformed and will be executed as-is. Please report this to the AutgoGraph team. When filing the bug, set the verbosity to 10 (on Linux, `export AUTOGRAPH_VERBOSITY=10`) and attach the full output. Cause: converting <bound method Conv.call of <tensorflow.python.layers.convolutional.Conv2D object at 0x13735bcc0>>: AssertionError: Bad argument number for Name: 3, expecting 4\n",
      "W0925 10:35:14.241466 4643411392 ag_logging.py:145] Entity <bound method Conv.call of <tensorflow.python.layers.convolutional.Conv2D object at 0x13735bcc0>> could not be transformed and will be executed as-is. Please report this to the AutgoGraph team. When filing the bug, set the verbosity to 10 (on Linux, `export AUTOGRAPH_VERBOSITY=10`) and attach the full output. Cause: converting <bound method Conv.call of <tensorflow.python.layers.convolutional.Conv2D object at 0x13735bcc0>>: AssertionError: Bad argument number for Name: 3, expecting 4\n",
      "WARNING:tensorflow:Entity <bound method BatchNormalization.call of <tensorflow.python.layers.normalization.BatchNormalization object at 0x1372674e0>> could not be transformed and will be executed as-is. Please report this to the AutgoGraph team. When filing the bug, set the verbosity to 10 (on Linux, `export AUTOGRAPH_VERBOSITY=10`) and attach the full output. Cause: converting <bound method BatchNormalization.call of <tensorflow.python.layers.normalization.BatchNormalization object at 0x1372674e0>>: AssertionError: Bad argument number for Name: 3, expecting 4\n",
      "W0925 10:35:14.287637 4643411392 ag_logging.py:145] Entity <bound method BatchNormalization.call of <tensorflow.python.layers.normalization.BatchNormalization object at 0x1372674e0>> could not be transformed and will be executed as-is. Please report this to the AutgoGraph team. When filing the bug, set the verbosity to 10 (on Linux, `export AUTOGRAPH_VERBOSITY=10`) and attach the full output. Cause: converting <bound method BatchNormalization.call of <tensorflow.python.layers.normalization.BatchNormalization object at 0x1372674e0>>: AssertionError: Bad argument number for Name: 3, expecting 4\n"
     ]
    },
    {
     "name": "stdout",
     "output_type": "stream",
     "text": [
      "WARNING:tensorflow:Entity <bound method Conv.call of <tensorflow.python.layers.convolutional.Conv2D object at 0x13737dc88>> could not be transformed and will be executed as-is. Please report this to the AutgoGraph team. When filing the bug, set the verbosity to 10 (on Linux, `export AUTOGRAPH_VERBOSITY=10`) and attach the full output. Cause: converting <bound method Conv.call of <tensorflow.python.layers.convolutional.Conv2D object at 0x13737dc88>>: AssertionError: Bad argument number for Name: 3, expecting 4\n",
      "W0925 10:35:14.397329 4643411392 ag_logging.py:145] Entity <bound method Conv.call of <tensorflow.python.layers.convolutional.Conv2D object at 0x13737dc88>> could not be transformed and will be executed as-is. Please report this to the AutgoGraph team. When filing the bug, set the verbosity to 10 (on Linux, `export AUTOGRAPH_VERBOSITY=10`) and attach the full output. Cause: converting <bound method Conv.call of <tensorflow.python.layers.convolutional.Conv2D object at 0x13737dc88>>: AssertionError: Bad argument number for Name: 3, expecting 4\n",
      "WARNING:tensorflow:Entity <bound method BatchNormalization.call of <tensorflow.python.layers.normalization.BatchNormalization object at 0x13745ac18>> could not be transformed and will be executed as-is. Please report this to the AutgoGraph team. When filing the bug, set the verbosity to 10 (on Linux, `export AUTOGRAPH_VERBOSITY=10`) and attach the full output. Cause: converting <bound method BatchNormalization.call of <tensorflow.python.layers.normalization.BatchNormalization object at 0x13745ac18>>: AssertionError: Bad argument number for Name: 3, expecting 4\n",
      "W0925 10:35:14.448981 4643411392 ag_logging.py:145] Entity <bound method BatchNormalization.call of <tensorflow.python.layers.normalization.BatchNormalization object at 0x13745ac18>> could not be transformed and will be executed as-is. Please report this to the AutgoGraph team. When filing the bug, set the verbosity to 10 (on Linux, `export AUTOGRAPH_VERBOSITY=10`) and attach the full output. Cause: converting <bound method BatchNormalization.call of <tensorflow.python.layers.normalization.BatchNormalization object at 0x13745ac18>>: AssertionError: Bad argument number for Name: 3, expecting 4\n",
      "WARNING:tensorflow:Entity <bound method Conv.call of <tensorflow.python.layers.convolutional.Conv2D object at 0x12665cba8>> could not be transformed and will be executed as-is. Please report this to the AutgoGraph team. When filing the bug, set the verbosity to 10 (on Linux, `export AUTOGRAPH_VERBOSITY=10`) and attach the full output. Cause: converting <bound method Conv.call of <tensorflow.python.layers.convolutional.Conv2D object at 0x12665cba8>>: AssertionError: Bad argument number for Name: 3, expecting 4\n",
      "W0925 10:35:14.551024 4643411392 ag_logging.py:145] Entity <bound method Conv.call of <tensorflow.python.layers.convolutional.Conv2D object at 0x12665cba8>> could not be transformed and will be executed as-is. Please report this to the AutgoGraph team. When filing the bug, set the verbosity to 10 (on Linux, `export AUTOGRAPH_VERBOSITY=10`) and attach the full output. Cause: converting <bound method Conv.call of <tensorflow.python.layers.convolutional.Conv2D object at 0x12665cba8>>: AssertionError: Bad argument number for Name: 3, expecting 4\n",
      "WARNING:tensorflow:Entity <bound method BatchNormalization.call of <tensorflow.python.layers.normalization.BatchNormalization object at 0x1265be588>> could not be transformed and will be executed as-is. Please report this to the AutgoGraph team. When filing the bug, set the verbosity to 10 (on Linux, `export AUTOGRAPH_VERBOSITY=10`) and attach the full output. Cause: converting <bound method BatchNormalization.call of <tensorflow.python.layers.normalization.BatchNormalization object at 0x1265be588>>: AssertionError: Bad argument number for Name: 3, expecting 4\n",
      "W0925 10:35:14.592271 4643411392 ag_logging.py:145] Entity <bound method BatchNormalization.call of <tensorflow.python.layers.normalization.BatchNormalization object at 0x1265be588>> could not be transformed and will be executed as-is. Please report this to the AutgoGraph team. When filing the bug, set the verbosity to 10 (on Linux, `export AUTOGRAPH_VERBOSITY=10`) and attach the full output. Cause: converting <bound method BatchNormalization.call of <tensorflow.python.layers.normalization.BatchNormalization object at 0x1265be588>>: AssertionError: Bad argument number for Name: 3, expecting 4\n",
      "WARNING:tensorflow:Entity <bound method Conv.call of <tensorflow.python.layers.convolutional.Conv2D object at 0x1374049e8>> could not be transformed and will be executed as-is. Please report this to the AutgoGraph team. When filing the bug, set the verbosity to 10 (on Linux, `export AUTOGRAPH_VERBOSITY=10`) and attach the full output. Cause: converting <bound method Conv.call of <tensorflow.python.layers.convolutional.Conv2D object at 0x1374049e8>>: AssertionError: Bad argument number for Name: 3, expecting 4\n",
      "W0925 10:35:14.679644 4643411392 ag_logging.py:145] Entity <bound method Conv.call of <tensorflow.python.layers.convolutional.Conv2D object at 0x1374049e8>> could not be transformed and will be executed as-is. Please report this to the AutgoGraph team. When filing the bug, set the verbosity to 10 (on Linux, `export AUTOGRAPH_VERBOSITY=10`) and attach the full output. Cause: converting <bound method Conv.call of <tensorflow.python.layers.convolutional.Conv2D object at 0x1374049e8>>: AssertionError: Bad argument number for Name: 3, expecting 4\n",
      "WARNING:tensorflow:Entity <bound method BatchNormalization.call of <tensorflow.python.layers.normalization.BatchNormalization object at 0x1265f7128>> could not be transformed and will be executed as-is. Please report this to the AutgoGraph team. When filing the bug, set the verbosity to 10 (on Linux, `export AUTOGRAPH_VERBOSITY=10`) and attach the full output. Cause: converting <bound method BatchNormalization.call of <tensorflow.python.layers.normalization.BatchNormalization object at 0x1265f7128>>: AssertionError: Bad argument number for Name: 3, expecting 4\n",
      "W0925 10:35:14.711044 4643411392 ag_logging.py:145] Entity <bound method BatchNormalization.call of <tensorflow.python.layers.normalization.BatchNormalization object at 0x1265f7128>> could not be transformed and will be executed as-is. Please report this to the AutgoGraph team. When filing the bug, set the verbosity to 10 (on Linux, `export AUTOGRAPH_VERBOSITY=10`) and attach the full output. Cause: converting <bound method BatchNormalization.call of <tensorflow.python.layers.normalization.BatchNormalization object at 0x1265f7128>>: AssertionError: Bad argument number for Name: 3, expecting 4\n",
      "WARNING:tensorflow:Entity <bound method Conv.call of <tensorflow.python.layers.convolutional.Conv2D object at 0x13745ab38>> could not be transformed and will be executed as-is. Please report this to the AutgoGraph team. When filing the bug, set the verbosity to 10 (on Linux, `export AUTOGRAPH_VERBOSITY=10`) and attach the full output. Cause: converting <bound method Conv.call of <tensorflow.python.layers.convolutional.Conv2D object at 0x13745ab38>>: AssertionError: Bad argument number for Name: 3, expecting 4\n",
      "W0925 10:35:14.773455 4643411392 ag_logging.py:145] Entity <bound method Conv.call of <tensorflow.python.layers.convolutional.Conv2D object at 0x13745ab38>> could not be transformed and will be executed as-is. Please report this to the AutgoGraph team. When filing the bug, set the verbosity to 10 (on Linux, `export AUTOGRAPH_VERBOSITY=10`) and attach the full output. Cause: converting <bound method Conv.call of <tensorflow.python.layers.convolutional.Conv2D object at 0x13745ab38>>: AssertionError: Bad argument number for Name: 3, expecting 4\n",
      "WARNING:tensorflow:Entity <bound method BatchNormalization.call of <tensorflow.python.layers.normalization.BatchNormalization object at 0x1265f7ac8>> could not be transformed and will be executed as-is. Please report this to the AutgoGraph team. When filing the bug, set the verbosity to 10 (on Linux, `export AUTOGRAPH_VERBOSITY=10`) and attach the full output. Cause: converting <bound method BatchNormalization.call of <tensorflow.python.layers.normalization.BatchNormalization object at 0x1265f7ac8>>: AssertionError: Bad argument number for Name: 3, expecting 4\n",
      "W0925 10:35:14.805424 4643411392 ag_logging.py:145] Entity <bound method BatchNormalization.call of <tensorflow.python.layers.normalization.BatchNormalization object at 0x1265f7ac8>> could not be transformed and will be executed as-is. Please report this to the AutgoGraph team. When filing the bug, set the verbosity to 10 (on Linux, `export AUTOGRAPH_VERBOSITY=10`) and attach the full output. Cause: converting <bound method BatchNormalization.call of <tensorflow.python.layers.normalization.BatchNormalization object at 0x1265f7ac8>>: AssertionError: Bad argument number for Name: 3, expecting 4\n"
     ]
    },
    {
     "name": "stdout",
     "output_type": "stream",
     "text": [
      "WARNING:tensorflow:Entity <bound method Conv.call of <tensorflow.python.layers.convolutional.Conv2D object at 0x137404a20>> could not be transformed and will be executed as-is. Please report this to the AutgoGraph team. When filing the bug, set the verbosity to 10 (on Linux, `export AUTOGRAPH_VERBOSITY=10`) and attach the full output. Cause: converting <bound method Conv.call of <tensorflow.python.layers.convolutional.Conv2D object at 0x137404a20>>: AssertionError: Bad argument number for Name: 3, expecting 4\n",
      "W0925 10:35:14.865767 4643411392 ag_logging.py:145] Entity <bound method Conv.call of <tensorflow.python.layers.convolutional.Conv2D object at 0x137404a20>> could not be transformed and will be executed as-is. Please report this to the AutgoGraph team. When filing the bug, set the verbosity to 10 (on Linux, `export AUTOGRAPH_VERBOSITY=10`) and attach the full output. Cause: converting <bound method Conv.call of <tensorflow.python.layers.convolutional.Conv2D object at 0x137404a20>>: AssertionError: Bad argument number for Name: 3, expecting 4\n",
      "WARNING:tensorflow:Entity <bound method BatchNormalization.call of <tensorflow.python.layers.normalization.BatchNormalization object at 0x12667b390>> could not be transformed and will be executed as-is. Please report this to the AutgoGraph team. When filing the bug, set the verbosity to 10 (on Linux, `export AUTOGRAPH_VERBOSITY=10`) and attach the full output. Cause: converting <bound method BatchNormalization.call of <tensorflow.python.layers.normalization.BatchNormalization object at 0x12667b390>>: AssertionError: Bad argument number for Name: 3, expecting 4\n",
      "W0925 10:35:14.895814 4643411392 ag_logging.py:145] Entity <bound method BatchNormalization.call of <tensorflow.python.layers.normalization.BatchNormalization object at 0x12667b390>> could not be transformed and will be executed as-is. Please report this to the AutgoGraph team. When filing the bug, set the verbosity to 10 (on Linux, `export AUTOGRAPH_VERBOSITY=10`) and attach the full output. Cause: converting <bound method BatchNormalization.call of <tensorflow.python.layers.normalization.BatchNormalization object at 0x12667b390>>: AssertionError: Bad argument number for Name: 3, expecting 4\n",
      "WARNING:tensorflow:Entity <bound method Conv.call of <tensorflow.python.layers.convolutional.Conv2D object at 0x13745a780>> could not be transformed and will be executed as-is. Please report this to the AutgoGraph team. When filing the bug, set the verbosity to 10 (on Linux, `export AUTOGRAPH_VERBOSITY=10`) and attach the full output. Cause: converting <bound method Conv.call of <tensorflow.python.layers.convolutional.Conv2D object at 0x13745a780>>: AssertionError: Bad argument number for Name: 3, expecting 4\n",
      "W0925 10:35:14.958292 4643411392 ag_logging.py:145] Entity <bound method Conv.call of <tensorflow.python.layers.convolutional.Conv2D object at 0x13745a780>> could not be transformed and will be executed as-is. Please report this to the AutgoGraph team. When filing the bug, set the verbosity to 10 (on Linux, `export AUTOGRAPH_VERBOSITY=10`) and attach the full output. Cause: converting <bound method Conv.call of <tensorflow.python.layers.convolutional.Conv2D object at 0x13745a780>>: AssertionError: Bad argument number for Name: 3, expecting 4\n",
      "WARNING:tensorflow:Entity <bound method BatchNormalization.call of <tensorflow.python.layers.normalization.BatchNormalization object at 0x12667e5f8>> could not be transformed and will be executed as-is. Please report this to the AutgoGraph team. When filing the bug, set the verbosity to 10 (on Linux, `export AUTOGRAPH_VERBOSITY=10`) and attach the full output. Cause: converting <bound method BatchNormalization.call of <tensorflow.python.layers.normalization.BatchNormalization object at 0x12667e5f8>>: AssertionError: Bad argument number for Name: 3, expecting 4\n",
      "W0925 10:35:14.985183 4643411392 ag_logging.py:145] Entity <bound method BatchNormalization.call of <tensorflow.python.layers.normalization.BatchNormalization object at 0x12667e5f8>> could not be transformed and will be executed as-is. Please report this to the AutgoGraph team. When filing the bug, set the verbosity to 10 (on Linux, `export AUTOGRAPH_VERBOSITY=10`) and attach the full output. Cause: converting <bound method BatchNormalization.call of <tensorflow.python.layers.normalization.BatchNormalization object at 0x12667e5f8>>: AssertionError: Bad argument number for Name: 3, expecting 4\n",
      "WARNING:tensorflow:Entity <bound method Conv.call of <tensorflow.python.layers.convolutional.Conv2D object at 0x1374bb550>> could not be transformed and will be executed as-is. Please report this to the AutgoGraph team. When filing the bug, set the verbosity to 10 (on Linux, `export AUTOGRAPH_VERBOSITY=10`) and attach the full output. Cause: converting <bound method Conv.call of <tensorflow.python.layers.convolutional.Conv2D object at 0x1374bb550>>: AssertionError: Bad argument number for Name: 3, expecting 4\n",
      "W0925 10:35:15.063535 4643411392 ag_logging.py:145] Entity <bound method Conv.call of <tensorflow.python.layers.convolutional.Conv2D object at 0x1374bb550>> could not be transformed and will be executed as-is. Please report this to the AutgoGraph team. When filing the bug, set the verbosity to 10 (on Linux, `export AUTOGRAPH_VERBOSITY=10`) and attach the full output. Cause: converting <bound method Conv.call of <tensorflow.python.layers.convolutional.Conv2D object at 0x1374bb550>>: AssertionError: Bad argument number for Name: 3, expecting 4\n",
      "WARNING:tensorflow:Entity <bound method BatchNormalization.call of <tensorflow.python.layers.normalization.BatchNormalization object at 0x13738fe10>> could not be transformed and will be executed as-is. Please report this to the AutgoGraph team. When filing the bug, set the verbosity to 10 (on Linux, `export AUTOGRAPH_VERBOSITY=10`) and attach the full output. Cause: converting <bound method BatchNormalization.call of <tensorflow.python.layers.normalization.BatchNormalization object at 0x13738fe10>>: AssertionError: Bad argument number for Name: 3, expecting 4\n",
      "W0925 10:35:15.109535 4643411392 ag_logging.py:145] Entity <bound method BatchNormalization.call of <tensorflow.python.layers.normalization.BatchNormalization object at 0x13738fe10>> could not be transformed and will be executed as-is. Please report this to the AutgoGraph team. When filing the bug, set the verbosity to 10 (on Linux, `export AUTOGRAPH_VERBOSITY=10`) and attach the full output. Cause: converting <bound method BatchNormalization.call of <tensorflow.python.layers.normalization.BatchNormalization object at 0x13738fe10>>: AssertionError: Bad argument number for Name: 3, expecting 4\n",
      "WARNING:tensorflow:Entity <bound method Conv.call of <tensorflow.python.layers.convolutional.Conv2D object at 0x12665cba8>> could not be transformed and will be executed as-is. Please report this to the AutgoGraph team. When filing the bug, set the verbosity to 10 (on Linux, `export AUTOGRAPH_VERBOSITY=10`) and attach the full output. Cause: converting <bound method Conv.call of <tensorflow.python.layers.convolutional.Conv2D object at 0x12665cba8>>: AssertionError: Bad argument number for Name: 3, expecting 4\n",
      "W0925 10:35:15.196826 4643411392 ag_logging.py:145] Entity <bound method Conv.call of <tensorflow.python.layers.convolutional.Conv2D object at 0x12665cba8>> could not be transformed and will be executed as-is. Please report this to the AutgoGraph team. When filing the bug, set the verbosity to 10 (on Linux, `export AUTOGRAPH_VERBOSITY=10`) and attach the full output. Cause: converting <bound method Conv.call of <tensorflow.python.layers.convolutional.Conv2D object at 0x12665cba8>>: AssertionError: Bad argument number for Name: 3, expecting 4\n",
      "WARNING:tensorflow:Entity <bound method BatchNormalization.call of <tensorflow.python.layers.normalization.BatchNormalization object at 0x13738fe10>> could not be transformed and will be executed as-is. Please report this to the AutgoGraph team. When filing the bug, set the verbosity to 10 (on Linux, `export AUTOGRAPH_VERBOSITY=10`) and attach the full output. Cause: converting <bound method BatchNormalization.call of <tensorflow.python.layers.normalization.BatchNormalization object at 0x13738fe10>>: AssertionError: Bad argument number for Name: 3, expecting 4\n",
      "W0925 10:35:15.237128 4643411392 ag_logging.py:145] Entity <bound method BatchNormalization.call of <tensorflow.python.layers.normalization.BatchNormalization object at 0x13738fe10>> could not be transformed and will be executed as-is. Please report this to the AutgoGraph team. When filing the bug, set the verbosity to 10 (on Linux, `export AUTOGRAPH_VERBOSITY=10`) and attach the full output. Cause: converting <bound method BatchNormalization.call of <tensorflow.python.layers.normalization.BatchNormalization object at 0x13738fe10>>: AssertionError: Bad argument number for Name: 3, expecting 4\n"
     ]
    },
    {
     "name": "stdout",
     "output_type": "stream",
     "text": [
      "WARNING:tensorflow:Entity <bound method Conv.call of <tensorflow.python.layers.convolutional.Conv2D object at 0x1374ece48>> could not be transformed and will be executed as-is. Please report this to the AutgoGraph team. When filing the bug, set the verbosity to 10 (on Linux, `export AUTOGRAPH_VERBOSITY=10`) and attach the full output. Cause: converting <bound method Conv.call of <tensorflow.python.layers.convolutional.Conv2D object at 0x1374ece48>>: AssertionError: Bad argument number for Name: 3, expecting 4\n",
      "W0925 10:35:15.328483 4643411392 ag_logging.py:145] Entity <bound method Conv.call of <tensorflow.python.layers.convolutional.Conv2D object at 0x1374ece48>> could not be transformed and will be executed as-is. Please report this to the AutgoGraph team. When filing the bug, set the verbosity to 10 (on Linux, `export AUTOGRAPH_VERBOSITY=10`) and attach the full output. Cause: converting <bound method Conv.call of <tensorflow.python.layers.convolutional.Conv2D object at 0x1374ece48>>: AssertionError: Bad argument number for Name: 3, expecting 4\n",
      "WARNING:tensorflow:Entity <bound method BatchNormalization.call of <tensorflow.python.layers.normalization.BatchNormalization object at 0x1375ca5c0>> could not be transformed and will be executed as-is. Please report this to the AutgoGraph team. When filing the bug, set the verbosity to 10 (on Linux, `export AUTOGRAPH_VERBOSITY=10`) and attach the full output. Cause: converting <bound method BatchNormalization.call of <tensorflow.python.layers.normalization.BatchNormalization object at 0x1375ca5c0>>: AssertionError: Bad argument number for Name: 3, expecting 4\n",
      "W0925 10:35:15.367694 4643411392 ag_logging.py:145] Entity <bound method BatchNormalization.call of <tensorflow.python.layers.normalization.BatchNormalization object at 0x1375ca5c0>> could not be transformed and will be executed as-is. Please report this to the AutgoGraph team. When filing the bug, set the verbosity to 10 (on Linux, `export AUTOGRAPH_VERBOSITY=10`) and attach the full output. Cause: converting <bound method BatchNormalization.call of <tensorflow.python.layers.normalization.BatchNormalization object at 0x1375ca5c0>>: AssertionError: Bad argument number for Name: 3, expecting 4\n",
      "WARNING:tensorflow:Entity <bound method Conv.call of <tensorflow.python.layers.convolutional.Conv2D object at 0x13738fe10>> could not be transformed and will be executed as-is. Please report this to the AutgoGraph team. When filing the bug, set the verbosity to 10 (on Linux, `export AUTOGRAPH_VERBOSITY=10`) and attach the full output. Cause: converting <bound method Conv.call of <tensorflow.python.layers.convolutional.Conv2D object at 0x13738fe10>>: AssertionError: Bad argument number for Name: 3, expecting 4\n",
      "W0925 10:35:15.452674 4643411392 ag_logging.py:145] Entity <bound method Conv.call of <tensorflow.python.layers.convolutional.Conv2D object at 0x13738fe10>> could not be transformed and will be executed as-is. Please report this to the AutgoGraph team. When filing the bug, set the verbosity to 10 (on Linux, `export AUTOGRAPH_VERBOSITY=10`) and attach the full output. Cause: converting <bound method Conv.call of <tensorflow.python.layers.convolutional.Conv2D object at 0x13738fe10>>: AssertionError: Bad argument number for Name: 3, expecting 4\n",
      "WARNING:tensorflow:Entity <bound method BatchNormalization.call of <tensorflow.python.layers.normalization.BatchNormalization object at 0x137404518>> could not be transformed and will be executed as-is. Please report this to the AutgoGraph team. When filing the bug, set the verbosity to 10 (on Linux, `export AUTOGRAPH_VERBOSITY=10`) and attach the full output. Cause: converting <bound method BatchNormalization.call of <tensorflow.python.layers.normalization.BatchNormalization object at 0x137404518>>: AssertionError: Bad argument number for Name: 3, expecting 4\n",
      "W0925 10:35:15.489114 4643411392 ag_logging.py:145] Entity <bound method BatchNormalization.call of <tensorflow.python.layers.normalization.BatchNormalization object at 0x137404518>> could not be transformed and will be executed as-is. Please report this to the AutgoGraph team. When filing the bug, set the verbosity to 10 (on Linux, `export AUTOGRAPH_VERBOSITY=10`) and attach the full output. Cause: converting <bound method BatchNormalization.call of <tensorflow.python.layers.normalization.BatchNormalization object at 0x137404518>>: AssertionError: Bad argument number for Name: 3, expecting 4\n",
      "WARNING:tensorflow:Entity <bound method Conv.call of <tensorflow.python.layers.convolutional.Conv2D object at 0x1374bb550>> could not be transformed and will be executed as-is. Please report this to the AutgoGraph team. When filing the bug, set the verbosity to 10 (on Linux, `export AUTOGRAPH_VERBOSITY=10`) and attach the full output. Cause: converting <bound method Conv.call of <tensorflow.python.layers.convolutional.Conv2D object at 0x1374bb550>>: AssertionError: Bad argument number for Name: 3, expecting 4\n",
      "W0925 10:35:15.569169 4643411392 ag_logging.py:145] Entity <bound method Conv.call of <tensorflow.python.layers.convolutional.Conv2D object at 0x1374bb550>> could not be transformed and will be executed as-is. Please report this to the AutgoGraph team. When filing the bug, set the verbosity to 10 (on Linux, `export AUTOGRAPH_VERBOSITY=10`) and attach the full output. Cause: converting <bound method Conv.call of <tensorflow.python.layers.convolutional.Conv2D object at 0x1374bb550>>: AssertionError: Bad argument number for Name: 3, expecting 4\n",
      "WARNING:tensorflow:Entity <bound method BatchNormalization.call of <tensorflow.python.layers.normalization.BatchNormalization object at 0x137437780>> could not be transformed and will be executed as-is. Please report this to the AutgoGraph team. When filing the bug, set the verbosity to 10 (on Linux, `export AUTOGRAPH_VERBOSITY=10`) and attach the full output. Cause: converting <bound method BatchNormalization.call of <tensorflow.python.layers.normalization.BatchNormalization object at 0x137437780>>: AssertionError: Bad argument number for Name: 3, expecting 4\n",
      "W0925 10:35:15.605285 4643411392 ag_logging.py:145] Entity <bound method BatchNormalization.call of <tensorflow.python.layers.normalization.BatchNormalization object at 0x137437780>> could not be transformed and will be executed as-is. Please report this to the AutgoGraph team. When filing the bug, set the verbosity to 10 (on Linux, `export AUTOGRAPH_VERBOSITY=10`) and attach the full output. Cause: converting <bound method BatchNormalization.call of <tensorflow.python.layers.normalization.BatchNormalization object at 0x137437780>>: AssertionError: Bad argument number for Name: 3, expecting 4\n",
      "WARNING:tensorflow:Entity <bound method Conv.call of <tensorflow.python.layers.convolutional.Conv2D object at 0x13738fcf8>> could not be transformed and will be executed as-is. Please report this to the AutgoGraph team. When filing the bug, set the verbosity to 10 (on Linux, `export AUTOGRAPH_VERBOSITY=10`) and attach the full output. Cause: converting <bound method Conv.call of <tensorflow.python.layers.convolutional.Conv2D object at 0x13738fcf8>>: AssertionError: Bad argument number for Name: 3, expecting 4\n",
      "W0925 10:35:15.688987 4643411392 ag_logging.py:145] Entity <bound method Conv.call of <tensorflow.python.layers.convolutional.Conv2D object at 0x13738fcf8>> could not be transformed and will be executed as-is. Please report this to the AutgoGraph team. When filing the bug, set the verbosity to 10 (on Linux, `export AUTOGRAPH_VERBOSITY=10`) and attach the full output. Cause: converting <bound method Conv.call of <tensorflow.python.layers.convolutional.Conv2D object at 0x13738fcf8>>: AssertionError: Bad argument number for Name: 3, expecting 4\n",
      "WARNING:tensorflow:Entity <bound method BatchNormalization.call of <tensorflow.python.layers.normalization.BatchNormalization object at 0x1375278d0>> could not be transformed and will be executed as-is. Please report this to the AutgoGraph team. When filing the bug, set the verbosity to 10 (on Linux, `export AUTOGRAPH_VERBOSITY=10`) and attach the full output. Cause: converting <bound method BatchNormalization.call of <tensorflow.python.layers.normalization.BatchNormalization object at 0x1375278d0>>: AssertionError: Bad argument number for Name: 3, expecting 4\n",
      "W0925 10:35:15.816431 4643411392 ag_logging.py:145] Entity <bound method BatchNormalization.call of <tensorflow.python.layers.normalization.BatchNormalization object at 0x1375278d0>> could not be transformed and will be executed as-is. Please report this to the AutgoGraph team. When filing the bug, set the verbosity to 10 (on Linux, `export AUTOGRAPH_VERBOSITY=10`) and attach the full output. Cause: converting <bound method BatchNormalization.call of <tensorflow.python.layers.normalization.BatchNormalization object at 0x1375278d0>>: AssertionError: Bad argument number for Name: 3, expecting 4\n"
     ]
    },
    {
     "name": "stdout",
     "output_type": "stream",
     "text": [
      "WARNING:tensorflow:Entity <bound method Conv.call of <tensorflow.python.layers.convolutional.Conv2D object at 0x1376df320>> could not be transformed and will be executed as-is. Please report this to the AutgoGraph team. When filing the bug, set the verbosity to 10 (on Linux, `export AUTOGRAPH_VERBOSITY=10`) and attach the full output. Cause: converting <bound method Conv.call of <tensorflow.python.layers.convolutional.Conv2D object at 0x1376df320>>: AssertionError: Bad argument number for Name: 3, expecting 4\n",
      "W0925 10:35:15.907087 4643411392 ag_logging.py:145] Entity <bound method Conv.call of <tensorflow.python.layers.convolutional.Conv2D object at 0x1376df320>> could not be transformed and will be executed as-is. Please report this to the AutgoGraph team. When filing the bug, set the verbosity to 10 (on Linux, `export AUTOGRAPH_VERBOSITY=10`) and attach the full output. Cause: converting <bound method Conv.call of <tensorflow.python.layers.convolutional.Conv2D object at 0x1376df320>>: AssertionError: Bad argument number for Name: 3, expecting 4\n",
      "WARNING:tensorflow:Entity <bound method BatchNormalization.call of <tensorflow.python.layers.normalization.BatchNormalization object at 0x1377a3630>> could not be transformed and will be executed as-is. Please report this to the AutgoGraph team. When filing the bug, set the verbosity to 10 (on Linux, `export AUTOGRAPH_VERBOSITY=10`) and attach the full output. Cause: converting <bound method BatchNormalization.call of <tensorflow.python.layers.normalization.BatchNormalization object at 0x1377a3630>>: AssertionError: Bad argument number for Name: 3, expecting 4\n",
      "W0925 10:35:15.944509 4643411392 ag_logging.py:145] Entity <bound method BatchNormalization.call of <tensorflow.python.layers.normalization.BatchNormalization object at 0x1377a3630>> could not be transformed and will be executed as-is. Please report this to the AutgoGraph team. When filing the bug, set the verbosity to 10 (on Linux, `export AUTOGRAPH_VERBOSITY=10`) and attach the full output. Cause: converting <bound method BatchNormalization.call of <tensorflow.python.layers.normalization.BatchNormalization object at 0x1377a3630>>: AssertionError: Bad argument number for Name: 3, expecting 4\n",
      "WARNING:tensorflow:Entity <bound method Conv.call of <tensorflow.python.layers.convolutional.Conv2D object at 0x1374bb550>> could not be transformed and will be executed as-is. Please report this to the AutgoGraph team. When filing the bug, set the verbosity to 10 (on Linux, `export AUTOGRAPH_VERBOSITY=10`) and attach the full output. Cause: converting <bound method Conv.call of <tensorflow.python.layers.convolutional.Conv2D object at 0x1374bb550>>: AssertionError: Bad argument number for Name: 3, expecting 4\n",
      "W0925 10:35:16.027470 4643411392 ag_logging.py:145] Entity <bound method Conv.call of <tensorflow.python.layers.convolutional.Conv2D object at 0x1374bb550>> could not be transformed and will be executed as-is. Please report this to the AutgoGraph team. When filing the bug, set the verbosity to 10 (on Linux, `export AUTOGRAPH_VERBOSITY=10`) and attach the full output. Cause: converting <bound method Conv.call of <tensorflow.python.layers.convolutional.Conv2D object at 0x1374bb550>>: AssertionError: Bad argument number for Name: 3, expecting 4\n",
      "WARNING:tensorflow:Entity <bound method BatchNormalization.call of <tensorflow.python.layers.normalization.BatchNormalization object at 0x13777ee48>> could not be transformed and will be executed as-is. Please report this to the AutgoGraph team. When filing the bug, set the verbosity to 10 (on Linux, `export AUTOGRAPH_VERBOSITY=10`) and attach the full output. Cause: converting <bound method BatchNormalization.call of <tensorflow.python.layers.normalization.BatchNormalization object at 0x13777ee48>>: AssertionError: Bad argument number for Name: 3, expecting 4\n",
      "W0925 10:35:16.064956 4643411392 ag_logging.py:145] Entity <bound method BatchNormalization.call of <tensorflow.python.layers.normalization.BatchNormalization object at 0x13777ee48>> could not be transformed and will be executed as-is. Please report this to the AutgoGraph team. When filing the bug, set the verbosity to 10 (on Linux, `export AUTOGRAPH_VERBOSITY=10`) and attach the full output. Cause: converting <bound method BatchNormalization.call of <tensorflow.python.layers.normalization.BatchNormalization object at 0x13777ee48>>: AssertionError: Bad argument number for Name: 3, expecting 4\n",
      "WARNING:tensorflow:Entity <bound method Conv.call of <tensorflow.python.layers.convolutional.Conv2D object at 0x137697a20>> could not be transformed and will be executed as-is. Please report this to the AutgoGraph team. When filing the bug, set the verbosity to 10 (on Linux, `export AUTOGRAPH_VERBOSITY=10`) and attach the full output. Cause: converting <bound method Conv.call of <tensorflow.python.layers.convolutional.Conv2D object at 0x137697a20>>: AssertionError: Bad argument number for Name: 3, expecting 4\n",
      "W0925 10:35:16.151176 4643411392 ag_logging.py:145] Entity <bound method Conv.call of <tensorflow.python.layers.convolutional.Conv2D object at 0x137697a20>> could not be transformed and will be executed as-is. Please report this to the AutgoGraph team. When filing the bug, set the verbosity to 10 (on Linux, `export AUTOGRAPH_VERBOSITY=10`) and attach the full output. Cause: converting <bound method Conv.call of <tensorflow.python.layers.convolutional.Conv2D object at 0x137697a20>>: AssertionError: Bad argument number for Name: 3, expecting 4\n",
      "WARNING:tensorflow:Entity <bound method BatchNormalization.call of <tensorflow.python.layers.normalization.BatchNormalization object at 0x137860e10>> could not be transformed and will be executed as-is. Please report this to the AutgoGraph team. When filing the bug, set the verbosity to 10 (on Linux, `export AUTOGRAPH_VERBOSITY=10`) and attach the full output. Cause: converting <bound method BatchNormalization.call of <tensorflow.python.layers.normalization.BatchNormalization object at 0x137860e10>>: AssertionError: Bad argument number for Name: 3, expecting 4\n",
      "W0925 10:35:16.188291 4643411392 ag_logging.py:145] Entity <bound method BatchNormalization.call of <tensorflow.python.layers.normalization.BatchNormalization object at 0x137860e10>> could not be transformed and will be executed as-is. Please report this to the AutgoGraph team. When filing the bug, set the verbosity to 10 (on Linux, `export AUTOGRAPH_VERBOSITY=10`) and attach the full output. Cause: converting <bound method BatchNormalization.call of <tensorflow.python.layers.normalization.BatchNormalization object at 0x137860e10>>: AssertionError: Bad argument number for Name: 3, expecting 4\n",
      "WARNING:tensorflow:Entity <bound method Conv.call of <tensorflow.python.layers.convolutional.Conv2D object at 0x1265f4d30>> could not be transformed and will be executed as-is. Please report this to the AutgoGraph team. When filing the bug, set the verbosity to 10 (on Linux, `export AUTOGRAPH_VERBOSITY=10`) and attach the full output. Cause: converting <bound method Conv.call of <tensorflow.python.layers.convolutional.Conv2D object at 0x1265f4d30>>: AssertionError: Bad argument number for Name: 3, expecting 4\n",
      "W0925 10:35:16.275429 4643411392 ag_logging.py:145] Entity <bound method Conv.call of <tensorflow.python.layers.convolutional.Conv2D object at 0x1265f4d30>> could not be transformed and will be executed as-is. Please report this to the AutgoGraph team. When filing the bug, set the verbosity to 10 (on Linux, `export AUTOGRAPH_VERBOSITY=10`) and attach the full output. Cause: converting <bound method Conv.call of <tensorflow.python.layers.convolutional.Conv2D object at 0x1265f4d30>>: AssertionError: Bad argument number for Name: 3, expecting 4\n",
      "WARNING:tensorflow:Entity <bound method BatchNormalization.call of <tensorflow.python.layers.normalization.BatchNormalization object at 0x13764cc50>> could not be transformed and will be executed as-is. Please report this to the AutgoGraph team. When filing the bug, set the verbosity to 10 (on Linux, `export AUTOGRAPH_VERBOSITY=10`) and attach the full output. Cause: converting <bound method BatchNormalization.call of <tensorflow.python.layers.normalization.BatchNormalization object at 0x13764cc50>>: AssertionError: Bad argument number for Name: 3, expecting 4\n",
      "W0925 10:35:16.322242 4643411392 ag_logging.py:145] Entity <bound method BatchNormalization.call of <tensorflow.python.layers.normalization.BatchNormalization object at 0x13764cc50>> could not be transformed and will be executed as-is. Please report this to the AutgoGraph team. When filing the bug, set the verbosity to 10 (on Linux, `export AUTOGRAPH_VERBOSITY=10`) and attach the full output. Cause: converting <bound method BatchNormalization.call of <tensorflow.python.layers.normalization.BatchNormalization object at 0x13764cc50>>: AssertionError: Bad argument number for Name: 3, expecting 4\n"
     ]
    },
    {
     "name": "stdout",
     "output_type": "stream",
     "text": [
      "WARNING:tensorflow:Entity <bound method Conv.call of <tensorflow.python.layers.convolutional.Conv2D object at 0x1378081d0>> could not be transformed and will be executed as-is. Please report this to the AutgoGraph team. When filing the bug, set the verbosity to 10 (on Linux, `export AUTOGRAPH_VERBOSITY=10`) and attach the full output. Cause: converting <bound method Conv.call of <tensorflow.python.layers.convolutional.Conv2D object at 0x1378081d0>>: AssertionError: Bad argument number for Name: 3, expecting 4\n",
      "W0925 10:35:16.412960 4643411392 ag_logging.py:145] Entity <bound method Conv.call of <tensorflow.python.layers.convolutional.Conv2D object at 0x1378081d0>> could not be transformed and will be executed as-is. Please report this to the AutgoGraph team. When filing the bug, set the verbosity to 10 (on Linux, `export AUTOGRAPH_VERBOSITY=10`) and attach the full output. Cause: converting <bound method Conv.call of <tensorflow.python.layers.convolutional.Conv2D object at 0x1378081d0>>: AssertionError: Bad argument number for Name: 3, expecting 4\n",
      "WARNING:tensorflow:Entity <bound method BatchNormalization.call of <tensorflow.python.layers.normalization.BatchNormalization object at 0x1376065f8>> could not be transformed and will be executed as-is. Please report this to the AutgoGraph team. When filing the bug, set the verbosity to 10 (on Linux, `export AUTOGRAPH_VERBOSITY=10`) and attach the full output. Cause: converting <bound method BatchNormalization.call of <tensorflow.python.layers.normalization.BatchNormalization object at 0x1376065f8>>: AssertionError: Bad argument number for Name: 3, expecting 4\n",
      "W0925 10:35:16.454035 4643411392 ag_logging.py:145] Entity <bound method BatchNormalization.call of <tensorflow.python.layers.normalization.BatchNormalization object at 0x1376065f8>> could not be transformed and will be executed as-is. Please report this to the AutgoGraph team. When filing the bug, set the verbosity to 10 (on Linux, `export AUTOGRAPH_VERBOSITY=10`) and attach the full output. Cause: converting <bound method BatchNormalization.call of <tensorflow.python.layers.normalization.BatchNormalization object at 0x1376065f8>>: AssertionError: Bad argument number for Name: 3, expecting 4\n",
      "WARNING:tensorflow:Entity <bound method Conv.call of <tensorflow.python.layers.convolutional.Conv2D object at 0x137860e10>> could not be transformed and will be executed as-is. Please report this to the AutgoGraph team. When filing the bug, set the verbosity to 10 (on Linux, `export AUTOGRAPH_VERBOSITY=10`) and attach the full output. Cause: converting <bound method Conv.call of <tensorflow.python.layers.convolutional.Conv2D object at 0x137860e10>>: AssertionError: Bad argument number for Name: 3, expecting 4\n",
      "W0925 10:35:16.536077 4643411392 ag_logging.py:145] Entity <bound method Conv.call of <tensorflow.python.layers.convolutional.Conv2D object at 0x137860e10>> could not be transformed and will be executed as-is. Please report this to the AutgoGraph team. When filing the bug, set the verbosity to 10 (on Linux, `export AUTOGRAPH_VERBOSITY=10`) and attach the full output. Cause: converting <bound method Conv.call of <tensorflow.python.layers.convolutional.Conv2D object at 0x137860e10>>: AssertionError: Bad argument number for Name: 3, expecting 4\n",
      "WARNING:tensorflow:Entity <bound method BatchNormalization.call of <tensorflow.python.layers.normalization.BatchNormalization object at 0x1376df748>> could not be transformed and will be executed as-is. Please report this to the AutgoGraph team. When filing the bug, set the verbosity to 10 (on Linux, `export AUTOGRAPH_VERBOSITY=10`) and attach the full output. Cause: converting <bound method BatchNormalization.call of <tensorflow.python.layers.normalization.BatchNormalization object at 0x1376df748>>: AssertionError: Bad argument number for Name: 3, expecting 4\n",
      "W0925 10:35:16.572602 4643411392 ag_logging.py:145] Entity <bound method BatchNormalization.call of <tensorflow.python.layers.normalization.BatchNormalization object at 0x1376df748>> could not be transformed and will be executed as-is. Please report this to the AutgoGraph team. When filing the bug, set the verbosity to 10 (on Linux, `export AUTOGRAPH_VERBOSITY=10`) and attach the full output. Cause: converting <bound method BatchNormalization.call of <tensorflow.python.layers.normalization.BatchNormalization object at 0x1376df748>>: AssertionError: Bad argument number for Name: 3, expecting 4\n",
      "WARNING:tensorflow:Entity <bound method Conv.call of <tensorflow.python.layers.convolutional.Conv2D object at 0x1375ca898>> could not be transformed and will be executed as-is. Please report this to the AutgoGraph team. When filing the bug, set the verbosity to 10 (on Linux, `export AUTOGRAPH_VERBOSITY=10`) and attach the full output. Cause: converting <bound method Conv.call of <tensorflow.python.layers.convolutional.Conv2D object at 0x1375ca898>>: AssertionError: Bad argument number for Name: 3, expecting 4\n",
      "W0925 10:35:16.658138 4643411392 ag_logging.py:145] Entity <bound method Conv.call of <tensorflow.python.layers.convolutional.Conv2D object at 0x1375ca898>> could not be transformed and will be executed as-is. Please report this to the AutgoGraph team. When filing the bug, set the verbosity to 10 (on Linux, `export AUTOGRAPH_VERBOSITY=10`) and attach the full output. Cause: converting <bound method Conv.call of <tensorflow.python.layers.convolutional.Conv2D object at 0x1375ca898>>: AssertionError: Bad argument number for Name: 3, expecting 4\n",
      "WARNING:tensorflow:Entity <bound method BatchNormalization.call of <tensorflow.python.layers.normalization.BatchNormalization object at 0x137729278>> could not be transformed and will be executed as-is. Please report this to the AutgoGraph team. When filing the bug, set the verbosity to 10 (on Linux, `export AUTOGRAPH_VERBOSITY=10`) and attach the full output. Cause: converting <bound method BatchNormalization.call of <tensorflow.python.layers.normalization.BatchNormalization object at 0x137729278>>: AssertionError: Bad argument number for Name: 3, expecting 4\n",
      "W0925 10:35:16.702745 4643411392 ag_logging.py:145] Entity <bound method BatchNormalization.call of <tensorflow.python.layers.normalization.BatchNormalization object at 0x137729278>> could not be transformed and will be executed as-is. Please report this to the AutgoGraph team. When filing the bug, set the verbosity to 10 (on Linux, `export AUTOGRAPH_VERBOSITY=10`) and attach the full output. Cause: converting <bound method BatchNormalization.call of <tensorflow.python.layers.normalization.BatchNormalization object at 0x137729278>>: AssertionError: Bad argument number for Name: 3, expecting 4\n",
      "WARNING:tensorflow:Entity <bound method Conv.call of <tensorflow.python.layers.convolutional.Conv2D object at 0x1378fcf98>> could not be transformed and will be executed as-is. Please report this to the AutgoGraph team. When filing the bug, set the verbosity to 10 (on Linux, `export AUTOGRAPH_VERBOSITY=10`) and attach the full output. Cause: converting <bound method Conv.call of <tensorflow.python.layers.convolutional.Conv2D object at 0x1378fcf98>>: AssertionError: Bad argument number for Name: 3, expecting 4\n",
      "W0925 10:35:16.772105 4643411392 ag_logging.py:145] Entity <bound method Conv.call of <tensorflow.python.layers.convolutional.Conv2D object at 0x1378fcf98>> could not be transformed and will be executed as-is. Please report this to the AutgoGraph team. When filing the bug, set the verbosity to 10 (on Linux, `export AUTOGRAPH_VERBOSITY=10`) and attach the full output. Cause: converting <bound method Conv.call of <tensorflow.python.layers.convolutional.Conv2D object at 0x1378fcf98>>: AssertionError: Bad argument number for Name: 3, expecting 4\n",
      "WARNING:tensorflow:Entity <bound method BatchNormalization.call of <tensorflow.python.layers.normalization.BatchNormalization object at 0x130883358>> could not be transformed and will be executed as-is. Please report this to the AutgoGraph team. When filing the bug, set the verbosity to 10 (on Linux, `export AUTOGRAPH_VERBOSITY=10`) and attach the full output. Cause: converting <bound method BatchNormalization.call of <tensorflow.python.layers.normalization.BatchNormalization object at 0x130883358>>: AssertionError: Bad argument number for Name: 3, expecting 4\n",
      "W0925 10:35:16.797798 4643411392 ag_logging.py:145] Entity <bound method BatchNormalization.call of <tensorflow.python.layers.normalization.BatchNormalization object at 0x130883358>> could not be transformed and will be executed as-is. Please report this to the AutgoGraph team. When filing the bug, set the verbosity to 10 (on Linux, `export AUTOGRAPH_VERBOSITY=10`) and attach the full output. Cause: converting <bound method BatchNormalization.call of <tensorflow.python.layers.normalization.BatchNormalization object at 0x130883358>>: AssertionError: Bad argument number for Name: 3, expecting 4\n"
     ]
    },
    {
     "name": "stdout",
     "output_type": "stream",
     "text": [
      "WARNING:tensorflow:Entity <bound method Conv.call of <tensorflow.python.layers.convolutional.Conv2D object at 0x1375ca860>> could not be transformed and will be executed as-is. Please report this to the AutgoGraph team. When filing the bug, set the verbosity to 10 (on Linux, `export AUTOGRAPH_VERBOSITY=10`) and attach the full output. Cause: converting <bound method Conv.call of <tensorflow.python.layers.convolutional.Conv2D object at 0x1375ca860>>: AssertionError: Bad argument number for Name: 3, expecting 4\n",
      "W0925 10:35:16.878991 4643411392 ag_logging.py:145] Entity <bound method Conv.call of <tensorflow.python.layers.convolutional.Conv2D object at 0x1375ca860>> could not be transformed and will be executed as-is. Please report this to the AutgoGraph team. When filing the bug, set the verbosity to 10 (on Linux, `export AUTOGRAPH_VERBOSITY=10`) and attach the full output. Cause: converting <bound method Conv.call of <tensorflow.python.layers.convolutional.Conv2D object at 0x1375ca860>>: AssertionError: Bad argument number for Name: 3, expecting 4\n",
      "WARNING:tensorflow:Entity <bound method BatchNormalization.call of <tensorflow.python.layers.normalization.BatchNormalization object at 0x130883550>> could not be transformed and will be executed as-is. Please report this to the AutgoGraph team. When filing the bug, set the verbosity to 10 (on Linux, `export AUTOGRAPH_VERBOSITY=10`) and attach the full output. Cause: converting <bound method BatchNormalization.call of <tensorflow.python.layers.normalization.BatchNormalization object at 0x130883550>>: AssertionError: Bad argument number for Name: 3, expecting 4\n",
      "W0925 10:35:16.905900 4643411392 ag_logging.py:145] Entity <bound method BatchNormalization.call of <tensorflow.python.layers.normalization.BatchNormalization object at 0x130883550>> could not be transformed and will be executed as-is. Please report this to the AutgoGraph team. When filing the bug, set the verbosity to 10 (on Linux, `export AUTOGRAPH_VERBOSITY=10`) and attach the full output. Cause: converting <bound method BatchNormalization.call of <tensorflow.python.layers.normalization.BatchNormalization object at 0x130883550>>: AssertionError: Bad argument number for Name: 3, expecting 4\n",
      "WARNING:tensorflow:Entity <bound method Conv.call of <tensorflow.python.layers.convolutional.Conv2D object at 0x1377fd710>> could not be transformed and will be executed as-is. Please report this to the AutgoGraph team. When filing the bug, set the verbosity to 10 (on Linux, `export AUTOGRAPH_VERBOSITY=10`) and attach the full output. Cause: converting <bound method Conv.call of <tensorflow.python.layers.convolutional.Conv2D object at 0x1377fd710>>: AssertionError: Bad argument number for Name: 3, expecting 4\n",
      "W0925 10:35:16.970181 4643411392 ag_logging.py:145] Entity <bound method Conv.call of <tensorflow.python.layers.convolutional.Conv2D object at 0x1377fd710>> could not be transformed and will be executed as-is. Please report this to the AutgoGraph team. When filing the bug, set the verbosity to 10 (on Linux, `export AUTOGRAPH_VERBOSITY=10`) and attach the full output. Cause: converting <bound method Conv.call of <tensorflow.python.layers.convolutional.Conv2D object at 0x1377fd710>>: AssertionError: Bad argument number for Name: 3, expecting 4\n",
      "WARNING:tensorflow:Entity <bound method BatchNormalization.call of <tensorflow.python.layers.normalization.BatchNormalization object at 0x13781efd0>> could not be transformed and will be executed as-is. Please report this to the AutgoGraph team. When filing the bug, set the verbosity to 10 (on Linux, `export AUTOGRAPH_VERBOSITY=10`) and attach the full output. Cause: converting <bound method BatchNormalization.call of <tensorflow.python.layers.normalization.BatchNormalization object at 0x13781efd0>>: AssertionError: Bad argument number for Name: 3, expecting 4\n",
      "W0925 10:35:16.998226 4643411392 ag_logging.py:145] Entity <bound method BatchNormalization.call of <tensorflow.python.layers.normalization.BatchNormalization object at 0x13781efd0>> could not be transformed and will be executed as-is. Please report this to the AutgoGraph team. When filing the bug, set the verbosity to 10 (on Linux, `export AUTOGRAPH_VERBOSITY=10`) and attach the full output. Cause: converting <bound method BatchNormalization.call of <tensorflow.python.layers.normalization.BatchNormalization object at 0x13781efd0>>: AssertionError: Bad argument number for Name: 3, expecting 4\n",
      "WARNING:tensorflow:Entity <bound method Conv.call of <tensorflow.python.layers.convolutional.Conv2D object at 0x130883550>> could not be transformed and will be executed as-is. Please report this to the AutgoGraph team. When filing the bug, set the verbosity to 10 (on Linux, `export AUTOGRAPH_VERBOSITY=10`) and attach the full output. Cause: converting <bound method Conv.call of <tensorflow.python.layers.convolutional.Conv2D object at 0x130883550>>: AssertionError: Bad argument number for Name: 3, expecting 4\n",
      "W0925 10:35:17.097387 4643411392 ag_logging.py:145] Entity <bound method Conv.call of <tensorflow.python.layers.convolutional.Conv2D object at 0x130883550>> could not be transformed and will be executed as-is. Please report this to the AutgoGraph team. When filing the bug, set the verbosity to 10 (on Linux, `export AUTOGRAPH_VERBOSITY=10`) and attach the full output. Cause: converting <bound method Conv.call of <tensorflow.python.layers.convolutional.Conv2D object at 0x130883550>>: AssertionError: Bad argument number for Name: 3, expecting 4\n",
      "WARNING:tensorflow:Entity <bound method BatchNormalization.call of <tensorflow.python.layers.normalization.BatchNormalization object at 0x13781eb00>> could not be transformed and will be executed as-is. Please report this to the AutgoGraph team. When filing the bug, set the verbosity to 10 (on Linux, `export AUTOGRAPH_VERBOSITY=10`) and attach the full output. Cause: converting <bound method BatchNormalization.call of <tensorflow.python.layers.normalization.BatchNormalization object at 0x13781eb00>>: AssertionError: Bad argument number for Name: 3, expecting 4\n",
      "W0925 10:35:17.146162 4643411392 ag_logging.py:145] Entity <bound method BatchNormalization.call of <tensorflow.python.layers.normalization.BatchNormalization object at 0x13781eb00>> could not be transformed and will be executed as-is. Please report this to the AutgoGraph team. When filing the bug, set the verbosity to 10 (on Linux, `export AUTOGRAPH_VERBOSITY=10`) and attach the full output. Cause: converting <bound method BatchNormalization.call of <tensorflow.python.layers.normalization.BatchNormalization object at 0x13781eb00>>: AssertionError: Bad argument number for Name: 3, expecting 4\n",
      "WARNING:tensorflow:Entity <bound method Conv.call of <tensorflow.python.layers.convolutional.Conv2D object at 0x1375ca860>> could not be transformed and will be executed as-is. Please report this to the AutgoGraph team. When filing the bug, set the verbosity to 10 (on Linux, `export AUTOGRAPH_VERBOSITY=10`) and attach the full output. Cause: converting <bound method Conv.call of <tensorflow.python.layers.convolutional.Conv2D object at 0x1375ca860>>: AssertionError: Bad argument number for Name: 3, expecting 4\n",
      "W0925 10:35:17.243582 4643411392 ag_logging.py:145] Entity <bound method Conv.call of <tensorflow.python.layers.convolutional.Conv2D object at 0x1375ca860>> could not be transformed and will be executed as-is. Please report this to the AutgoGraph team. When filing the bug, set the verbosity to 10 (on Linux, `export AUTOGRAPH_VERBOSITY=10`) and attach the full output. Cause: converting <bound method Conv.call of <tensorflow.python.layers.convolutional.Conv2D object at 0x1375ca860>>: AssertionError: Bad argument number for Name: 3, expecting 4\n",
      "WARNING:tensorflow:Entity <bound method BatchNormalization.call of <tensorflow.python.layers.normalization.BatchNormalization object at 0x13781eb00>> could not be transformed and will be executed as-is. Please report this to the AutgoGraph team. When filing the bug, set the verbosity to 10 (on Linux, `export AUTOGRAPH_VERBOSITY=10`) and attach the full output. Cause: converting <bound method BatchNormalization.call of <tensorflow.python.layers.normalization.BatchNormalization object at 0x13781eb00>>: AssertionError: Bad argument number for Name: 3, expecting 4\n",
      "W0925 10:35:17.287606 4643411392 ag_logging.py:145] Entity <bound method BatchNormalization.call of <tensorflow.python.layers.normalization.BatchNormalization object at 0x13781eb00>> could not be transformed and will be executed as-is. Please report this to the AutgoGraph team. When filing the bug, set the verbosity to 10 (on Linux, `export AUTOGRAPH_VERBOSITY=10`) and attach the full output. Cause: converting <bound method BatchNormalization.call of <tensorflow.python.layers.normalization.BatchNormalization object at 0x13781eb00>>: AssertionError: Bad argument number for Name: 3, expecting 4\n"
     ]
    },
    {
     "name": "stdout",
     "output_type": "stream",
     "text": [
      "WARNING:tensorflow:Entity <bound method Conv.call of <tensorflow.python.layers.convolutional.Conv2D object at 0x13795e630>> could not be transformed and will be executed as-is. Please report this to the AutgoGraph team. When filing the bug, set the verbosity to 10 (on Linux, `export AUTOGRAPH_VERBOSITY=10`) and attach the full output. Cause: converting <bound method Conv.call of <tensorflow.python.layers.convolutional.Conv2D object at 0x13795e630>>: AssertionError: Bad argument number for Name: 3, expecting 4\n",
      "W0925 10:35:17.409800 4643411392 ag_logging.py:145] Entity <bound method Conv.call of <tensorflow.python.layers.convolutional.Conv2D object at 0x13795e630>> could not be transformed and will be executed as-is. Please report this to the AutgoGraph team. When filing the bug, set the verbosity to 10 (on Linux, `export AUTOGRAPH_VERBOSITY=10`) and attach the full output. Cause: converting <bound method Conv.call of <tensorflow.python.layers.convolutional.Conv2D object at 0x13795e630>>: AssertionError: Bad argument number for Name: 3, expecting 4\n",
      "WARNING:tensorflow:Entity <bound method BatchNormalization.call of <tensorflow.python.layers.normalization.BatchNormalization object at 0x1379d9da0>> could not be transformed and will be executed as-is. Please report this to the AutgoGraph team. When filing the bug, set the verbosity to 10 (on Linux, `export AUTOGRAPH_VERBOSITY=10`) and attach the full output. Cause: converting <bound method BatchNormalization.call of <tensorflow.python.layers.normalization.BatchNormalization object at 0x1379d9da0>>: AssertionError: Bad argument number for Name: 3, expecting 4\n",
      "W0925 10:35:17.451467 4643411392 ag_logging.py:145] Entity <bound method BatchNormalization.call of <tensorflow.python.layers.normalization.BatchNormalization object at 0x1379d9da0>> could not be transformed and will be executed as-is. Please report this to the AutgoGraph team. When filing the bug, set the verbosity to 10 (on Linux, `export AUTOGRAPH_VERBOSITY=10`) and attach the full output. Cause: converting <bound method BatchNormalization.call of <tensorflow.python.layers.normalization.BatchNormalization object at 0x1379d9da0>>: AssertionError: Bad argument number for Name: 3, expecting 4\n",
      "WARNING:tensorflow:Entity <bound method Conv.call of <tensorflow.python.layers.convolutional.Conv2D object at 0x137ae6e10>> could not be transformed and will be executed as-is. Please report this to the AutgoGraph team. When filing the bug, set the verbosity to 10 (on Linux, `export AUTOGRAPH_VERBOSITY=10`) and attach the full output. Cause: converting <bound method Conv.call of <tensorflow.python.layers.convolutional.Conv2D object at 0x137ae6e10>>: AssertionError: Bad argument number for Name: 3, expecting 4\n",
      "W0925 10:35:17.546301 4643411392 ag_logging.py:145] Entity <bound method Conv.call of <tensorflow.python.layers.convolutional.Conv2D object at 0x137ae6e10>> could not be transformed and will be executed as-is. Please report this to the AutgoGraph team. When filing the bug, set the verbosity to 10 (on Linux, `export AUTOGRAPH_VERBOSITY=10`) and attach the full output. Cause: converting <bound method Conv.call of <tensorflow.python.layers.convolutional.Conv2D object at 0x137ae6e10>>: AssertionError: Bad argument number for Name: 3, expecting 4\n",
      "WARNING:tensorflow:Entity <bound method BatchNormalization.call of <tensorflow.python.layers.normalization.BatchNormalization object at 0x1378e23c8>> could not be transformed and will be executed as-is. Please report this to the AutgoGraph team. When filing the bug, set the verbosity to 10 (on Linux, `export AUTOGRAPH_VERBOSITY=10`) and attach the full output. Cause: converting <bound method BatchNormalization.call of <tensorflow.python.layers.normalization.BatchNormalization object at 0x1378e23c8>>: AssertionError: Bad argument number for Name: 3, expecting 4\n",
      "W0925 10:35:17.617640 4643411392 ag_logging.py:145] Entity <bound method BatchNormalization.call of <tensorflow.python.layers.normalization.BatchNormalization object at 0x1378e23c8>> could not be transformed and will be executed as-is. Please report this to the AutgoGraph team. When filing the bug, set the verbosity to 10 (on Linux, `export AUTOGRAPH_VERBOSITY=10`) and attach the full output. Cause: converting <bound method BatchNormalization.call of <tensorflow.python.layers.normalization.BatchNormalization object at 0x1378e23c8>>: AssertionError: Bad argument number for Name: 3, expecting 4\n",
      "WARNING:tensorflow:Entity <bound method Conv.call of <tensorflow.python.layers.convolutional.Conv2D object at 0x137990fd0>> could not be transformed and will be executed as-is. Please report this to the AutgoGraph team. When filing the bug, set the verbosity to 10 (on Linux, `export AUTOGRAPH_VERBOSITY=10`) and attach the full output. Cause: converting <bound method Conv.call of <tensorflow.python.layers.convolutional.Conv2D object at 0x137990fd0>>: AssertionError: Bad argument number for Name: 3, expecting 4\n",
      "W0925 10:35:17.755897 4643411392 ag_logging.py:145] Entity <bound method Conv.call of <tensorflow.python.layers.convolutional.Conv2D object at 0x137990fd0>> could not be transformed and will be executed as-is. Please report this to the AutgoGraph team. When filing the bug, set the verbosity to 10 (on Linux, `export AUTOGRAPH_VERBOSITY=10`) and attach the full output. Cause: converting <bound method Conv.call of <tensorflow.python.layers.convolutional.Conv2D object at 0x137990fd0>>: AssertionError: Bad argument number for Name: 3, expecting 4\n",
      "WARNING:tensorflow:Entity <bound method BatchNormalization.call of <tensorflow.python.layers.normalization.BatchNormalization object at 0x13791a518>> could not be transformed and will be executed as-is. Please report this to the AutgoGraph team. When filing the bug, set the verbosity to 10 (on Linux, `export AUTOGRAPH_VERBOSITY=10`) and attach the full output. Cause: converting <bound method BatchNormalization.call of <tensorflow.python.layers.normalization.BatchNormalization object at 0x13791a518>>: AssertionError: Bad argument number for Name: 3, expecting 4\n",
      "W0925 10:35:17.819797 4643411392 ag_logging.py:145] Entity <bound method BatchNormalization.call of <tensorflow.python.layers.normalization.BatchNormalization object at 0x13791a518>> could not be transformed and will be executed as-is. Please report this to the AutgoGraph team. When filing the bug, set the verbosity to 10 (on Linux, `export AUTOGRAPH_VERBOSITY=10`) and attach the full output. Cause: converting <bound method BatchNormalization.call of <tensorflow.python.layers.normalization.BatchNormalization object at 0x13791a518>>: AssertionError: Bad argument number for Name: 3, expecting 4\n",
      "WARNING:tensorflow:Entity <bound method Conv.call of <tensorflow.python.layers.convolutional.Conv2D object at 0x137ae6908>> could not be transformed and will be executed as-is. Please report this to the AutgoGraph team. When filing the bug, set the verbosity to 10 (on Linux, `export AUTOGRAPH_VERBOSITY=10`) and attach the full output. Cause: converting <bound method Conv.call of <tensorflow.python.layers.convolutional.Conv2D object at 0x137ae6908>>: AssertionError: Bad argument number for Name: 3, expecting 4\n",
      "W0925 10:35:17.948922 4643411392 ag_logging.py:145] Entity <bound method Conv.call of <tensorflow.python.layers.convolutional.Conv2D object at 0x137ae6908>> could not be transformed and will be executed as-is. Please report this to the AutgoGraph team. When filing the bug, set the verbosity to 10 (on Linux, `export AUTOGRAPH_VERBOSITY=10`) and attach the full output. Cause: converting <bound method Conv.call of <tensorflow.python.layers.convolutional.Conv2D object at 0x137ae6908>>: AssertionError: Bad argument number for Name: 3, expecting 4\n",
      "WARNING:tensorflow:Entity <bound method BatchNormalization.call of <tensorflow.python.layers.normalization.BatchNormalization object at 0x13795e828>> could not be transformed and will be executed as-is. Please report this to the AutgoGraph team. When filing the bug, set the verbosity to 10 (on Linux, `export AUTOGRAPH_VERBOSITY=10`) and attach the full output. Cause: converting <bound method BatchNormalization.call of <tensorflow.python.layers.normalization.BatchNormalization object at 0x13795e828>>: AssertionError: Bad argument number for Name: 3, expecting 4\n",
      "W0925 10:35:18.008599 4643411392 ag_logging.py:145] Entity <bound method BatchNormalization.call of <tensorflow.python.layers.normalization.BatchNormalization object at 0x13795e828>> could not be transformed and will be executed as-is. Please report this to the AutgoGraph team. When filing the bug, set the verbosity to 10 (on Linux, `export AUTOGRAPH_VERBOSITY=10`) and attach the full output. Cause: converting <bound method BatchNormalization.call of <tensorflow.python.layers.normalization.BatchNormalization object at 0x13795e828>>: AssertionError: Bad argument number for Name: 3, expecting 4\n"
     ]
    },
    {
     "name": "stdout",
     "output_type": "stream",
     "text": [
      "WARNING:tensorflow:Entity <bound method Conv.call of <tensorflow.python.layers.convolutional.Conv2D object at 0x137a371d0>> could not be transformed and will be executed as-is. Please report this to the AutgoGraph team. When filing the bug, set the verbosity to 10 (on Linux, `export AUTOGRAPH_VERBOSITY=10`) and attach the full output. Cause: converting <bound method Conv.call of <tensorflow.python.layers.convolutional.Conv2D object at 0x137a371d0>>: AssertionError: Bad argument number for Name: 3, expecting 4\n",
      "W0925 10:35:18.132040 4643411392 ag_logging.py:145] Entity <bound method Conv.call of <tensorflow.python.layers.convolutional.Conv2D object at 0x137a371d0>> could not be transformed and will be executed as-is. Please report this to the AutgoGraph team. When filing the bug, set the verbosity to 10 (on Linux, `export AUTOGRAPH_VERBOSITY=10`) and attach the full output. Cause: converting <bound method Conv.call of <tensorflow.python.layers.convolutional.Conv2D object at 0x137a371d0>>: AssertionError: Bad argument number for Name: 3, expecting 4\n",
      "WARNING:tensorflow:Entity <bound method BatchNormalization.call of <tensorflow.python.layers.normalization.BatchNormalization object at 0x13795ea58>> could not be transformed and will be executed as-is. Please report this to the AutgoGraph team. When filing the bug, set the verbosity to 10 (on Linux, `export AUTOGRAPH_VERBOSITY=10`) and attach the full output. Cause: converting <bound method BatchNormalization.call of <tensorflow.python.layers.normalization.BatchNormalization object at 0x13795ea58>>: AssertionError: Bad argument number for Name: 3, expecting 4\n",
      "W0925 10:35:18.182824 4643411392 ag_logging.py:145] Entity <bound method BatchNormalization.call of <tensorflow.python.layers.normalization.BatchNormalization object at 0x13795ea58>> could not be transformed and will be executed as-is. Please report this to the AutgoGraph team. When filing the bug, set the verbosity to 10 (on Linux, `export AUTOGRAPH_VERBOSITY=10`) and attach the full output. Cause: converting <bound method BatchNormalization.call of <tensorflow.python.layers.normalization.BatchNormalization object at 0x13795ea58>>: AssertionError: Bad argument number for Name: 3, expecting 4\n",
      "WARNING:tensorflow:Entity <bound method Conv.call of <tensorflow.python.layers.convolutional.Conv2D object at 0x137990fd0>> could not be transformed and will be executed as-is. Please report this to the AutgoGraph team. When filing the bug, set the verbosity to 10 (on Linux, `export AUTOGRAPH_VERBOSITY=10`) and attach the full output. Cause: converting <bound method Conv.call of <tensorflow.python.layers.convolutional.Conv2D object at 0x137990fd0>>: AssertionError: Bad argument number for Name: 3, expecting 4\n",
      "W0925 10:35:18.277637 4643411392 ag_logging.py:145] Entity <bound method Conv.call of <tensorflow.python.layers.convolutional.Conv2D object at 0x137990fd0>> could not be transformed and will be executed as-is. Please report this to the AutgoGraph team. When filing the bug, set the verbosity to 10 (on Linux, `export AUTOGRAPH_VERBOSITY=10`) and attach the full output. Cause: converting <bound method Conv.call of <tensorflow.python.layers.convolutional.Conv2D object at 0x137990fd0>>: AssertionError: Bad argument number for Name: 3, expecting 4\n",
      "WARNING:tensorflow:Entity <bound method BatchNormalization.call of <tensorflow.python.layers.normalization.BatchNormalization object at 0x13795ea58>> could not be transformed and will be executed as-is. Please report this to the AutgoGraph team. When filing the bug, set the verbosity to 10 (on Linux, `export AUTOGRAPH_VERBOSITY=10`) and attach the full output. Cause: converting <bound method BatchNormalization.call of <tensorflow.python.layers.normalization.BatchNormalization object at 0x13795ea58>>: AssertionError: Bad argument number for Name: 3, expecting 4\n",
      "W0925 10:35:18.317731 4643411392 ag_logging.py:145] Entity <bound method BatchNormalization.call of <tensorflow.python.layers.normalization.BatchNormalization object at 0x13795ea58>> could not be transformed and will be executed as-is. Please report this to the AutgoGraph team. When filing the bug, set the verbosity to 10 (on Linux, `export AUTOGRAPH_VERBOSITY=10`) and attach the full output. Cause: converting <bound method BatchNormalization.call of <tensorflow.python.layers.normalization.BatchNormalization object at 0x13795ea58>>: AssertionError: Bad argument number for Name: 3, expecting 4\n",
      "WARNING:tensorflow:Entity <bound method Conv.call of <tensorflow.python.layers.convolutional.Conv2D object at 0x137a37208>> could not be transformed and will be executed as-is. Please report this to the AutgoGraph team. When filing the bug, set the verbosity to 10 (on Linux, `export AUTOGRAPH_VERBOSITY=10`) and attach the full output. Cause: converting <bound method Conv.call of <tensorflow.python.layers.convolutional.Conv2D object at 0x137a37208>>: AssertionError: Bad argument number for Name: 3, expecting 4\n",
      "W0925 10:35:18.424535 4643411392 ag_logging.py:145] Entity <bound method Conv.call of <tensorflow.python.layers.convolutional.Conv2D object at 0x137a37208>> could not be transformed and will be executed as-is. Please report this to the AutgoGraph team. When filing the bug, set the verbosity to 10 (on Linux, `export AUTOGRAPH_VERBOSITY=10`) and attach the full output. Cause: converting <bound method Conv.call of <tensorflow.python.layers.convolutional.Conv2D object at 0x137a37208>>: AssertionError: Bad argument number for Name: 3, expecting 4\n",
      "WARNING:tensorflow:Entity <bound method BatchNormalization.call of <tensorflow.python.layers.normalization.BatchNormalization object at 0x137a37198>> could not be transformed and will be executed as-is. Please report this to the AutgoGraph team. When filing the bug, set the verbosity to 10 (on Linux, `export AUTOGRAPH_VERBOSITY=10`) and attach the full output. Cause: converting <bound method BatchNormalization.call of <tensorflow.python.layers.normalization.BatchNormalization object at 0x137a37198>>: AssertionError: Bad argument number for Name: 3, expecting 4\n",
      "W0925 10:35:18.471779 4643411392 ag_logging.py:145] Entity <bound method BatchNormalization.call of <tensorflow.python.layers.normalization.BatchNormalization object at 0x137a37198>> could not be transformed and will be executed as-is. Please report this to the AutgoGraph team. When filing the bug, set the verbosity to 10 (on Linux, `export AUTOGRAPH_VERBOSITY=10`) and attach the full output. Cause: converting <bound method BatchNormalization.call of <tensorflow.python.layers.normalization.BatchNormalization object at 0x137a37198>>: AssertionError: Bad argument number for Name: 3, expecting 4\n",
      "WARNING:tensorflow:Entity <bound method Conv.call of <tensorflow.python.layers.convolutional.Conv2D object at 0x137a371d0>> could not be transformed and will be executed as-is. Please report this to the AutgoGraph team. When filing the bug, set the verbosity to 10 (on Linux, `export AUTOGRAPH_VERBOSITY=10`) and attach the full output. Cause: converting <bound method Conv.call of <tensorflow.python.layers.convolutional.Conv2D object at 0x137a371d0>>: AssertionError: Bad argument number for Name: 3, expecting 4\n",
      "W0925 10:35:18.579429 4643411392 ag_logging.py:145] Entity <bound method Conv.call of <tensorflow.python.layers.convolutional.Conv2D object at 0x137a371d0>> could not be transformed and will be executed as-is. Please report this to the AutgoGraph team. When filing the bug, set the verbosity to 10 (on Linux, `export AUTOGRAPH_VERBOSITY=10`) and attach the full output. Cause: converting <bound method Conv.call of <tensorflow.python.layers.convolutional.Conv2D object at 0x137a371d0>>: AssertionError: Bad argument number for Name: 3, expecting 4\n",
      "WARNING:tensorflow:Entity <bound method BatchNormalization.call of <tensorflow.python.layers.normalization.BatchNormalization object at 0x137b01f60>> could not be transformed and will be executed as-is. Please report this to the AutgoGraph team. When filing the bug, set the verbosity to 10 (on Linux, `export AUTOGRAPH_VERBOSITY=10`) and attach the full output. Cause: converting <bound method BatchNormalization.call of <tensorflow.python.layers.normalization.BatchNormalization object at 0x137b01f60>>: AssertionError: Bad argument number for Name: 3, expecting 4\n",
      "W0925 10:35:18.624397 4643411392 ag_logging.py:145] Entity <bound method BatchNormalization.call of <tensorflow.python.layers.normalization.BatchNormalization object at 0x137b01f60>> could not be transformed and will be executed as-is. Please report this to the AutgoGraph team. When filing the bug, set the verbosity to 10 (on Linux, `export AUTOGRAPH_VERBOSITY=10`) and attach the full output. Cause: converting <bound method BatchNormalization.call of <tensorflow.python.layers.normalization.BatchNormalization object at 0x137b01f60>>: AssertionError: Bad argument number for Name: 3, expecting 4\n"
     ]
    },
    {
     "name": "stdout",
     "output_type": "stream",
     "text": [
      "WARNING:tensorflow:Entity <bound method Conv.call of <tensorflow.python.layers.convolutional.Conv2D object at 0x137c40828>> could not be transformed and will be executed as-is. Please report this to the AutgoGraph team. When filing the bug, set the verbosity to 10 (on Linux, `export AUTOGRAPH_VERBOSITY=10`) and attach the full output. Cause: converting <bound method Conv.call of <tensorflow.python.layers.convolutional.Conv2D object at 0x137c40828>>: AssertionError: Bad argument number for Name: 3, expecting 4\n",
      "W0925 10:35:18.721447 4643411392 ag_logging.py:145] Entity <bound method Conv.call of <tensorflow.python.layers.convolutional.Conv2D object at 0x137c40828>> could not be transformed and will be executed as-is. Please report this to the AutgoGraph team. When filing the bug, set the verbosity to 10 (on Linux, `export AUTOGRAPH_VERBOSITY=10`) and attach the full output. Cause: converting <bound method Conv.call of <tensorflow.python.layers.convolutional.Conv2D object at 0x137c40828>>: AssertionError: Bad argument number for Name: 3, expecting 4\n",
      "WARNING:tensorflow:Entity <bound method BatchNormalization.call of <tensorflow.python.layers.normalization.BatchNormalization object at 0x137cfbfd0>> could not be transformed and will be executed as-is. Please report this to the AutgoGraph team. When filing the bug, set the verbosity to 10 (on Linux, `export AUTOGRAPH_VERBOSITY=10`) and attach the full output. Cause: converting <bound method BatchNormalization.call of <tensorflow.python.layers.normalization.BatchNormalization object at 0x137cfbfd0>>: AssertionError: Bad argument number for Name: 3, expecting 4\n",
      "W0925 10:35:18.745818 4643411392 ag_logging.py:145] Entity <bound method BatchNormalization.call of <tensorflow.python.layers.normalization.BatchNormalization object at 0x137cfbfd0>> could not be transformed and will be executed as-is. Please report this to the AutgoGraph team. When filing the bug, set the verbosity to 10 (on Linux, `export AUTOGRAPH_VERBOSITY=10`) and attach the full output. Cause: converting <bound method BatchNormalization.call of <tensorflow.python.layers.normalization.BatchNormalization object at 0x137cfbfd0>>: AssertionError: Bad argument number for Name: 3, expecting 4\n",
      "WARNING:tensorflow:Entity <bound method Conv.call of <tensorflow.python.layers.convolutional.Conv2D object at 0x137d5e1d0>> could not be transformed and will be executed as-is. Please report this to the AutgoGraph team. When filing the bug, set the verbosity to 10 (on Linux, `export AUTOGRAPH_VERBOSITY=10`) and attach the full output. Cause: converting <bound method Conv.call of <tensorflow.python.layers.convolutional.Conv2D object at 0x137d5e1d0>>: AssertionError: Bad argument number for Name: 3, expecting 4\n",
      "W0925 10:35:18.811355 4643411392 ag_logging.py:145] Entity <bound method Conv.call of <tensorflow.python.layers.convolutional.Conv2D object at 0x137d5e1d0>> could not be transformed and will be executed as-is. Please report this to the AutgoGraph team. When filing the bug, set the verbosity to 10 (on Linux, `export AUTOGRAPH_VERBOSITY=10`) and attach the full output. Cause: converting <bound method Conv.call of <tensorflow.python.layers.convolutional.Conv2D object at 0x137d5e1d0>>: AssertionError: Bad argument number for Name: 3, expecting 4\n",
      "WARNING:tensorflow:Entity <bound method BatchNormalization.call of <tensorflow.python.layers.normalization.BatchNormalization object at 0x137cfbd68>> could not be transformed and will be executed as-is. Please report this to the AutgoGraph team. When filing the bug, set the verbosity to 10 (on Linux, `export AUTOGRAPH_VERBOSITY=10`) and attach the full output. Cause: converting <bound method BatchNormalization.call of <tensorflow.python.layers.normalization.BatchNormalization object at 0x137cfbd68>>: AssertionError: Bad argument number for Name: 3, expecting 4\n",
      "W0925 10:35:18.837786 4643411392 ag_logging.py:145] Entity <bound method BatchNormalization.call of <tensorflow.python.layers.normalization.BatchNormalization object at 0x137cfbd68>> could not be transformed and will be executed as-is. Please report this to the AutgoGraph team. When filing the bug, set the verbosity to 10 (on Linux, `export AUTOGRAPH_VERBOSITY=10`) and attach the full output. Cause: converting <bound method BatchNormalization.call of <tensorflow.python.layers.normalization.BatchNormalization object at 0x137cfbd68>>: AssertionError: Bad argument number for Name: 3, expecting 4\n",
      "WARNING:tensorflow:Entity <bound method Conv.call of <tensorflow.python.layers.convolutional.Conv2D object at 0x137c99cc0>> could not be transformed and will be executed as-is. Please report this to the AutgoGraph team. When filing the bug, set the verbosity to 10 (on Linux, `export AUTOGRAPH_VERBOSITY=10`) and attach the full output. Cause: converting <bound method Conv.call of <tensorflow.python.layers.convolutional.Conv2D object at 0x137c99cc0>>: AssertionError: Bad argument number for Name: 3, expecting 4\n",
      "W0925 10:35:18.910700 4643411392 ag_logging.py:145] Entity <bound method Conv.call of <tensorflow.python.layers.convolutional.Conv2D object at 0x137c99cc0>> could not be transformed and will be executed as-is. Please report this to the AutgoGraph team. When filing the bug, set the verbosity to 10 (on Linux, `export AUTOGRAPH_VERBOSITY=10`) and attach the full output. Cause: converting <bound method Conv.call of <tensorflow.python.layers.convolutional.Conv2D object at 0x137c99cc0>>: AssertionError: Bad argument number for Name: 3, expecting 4\n",
      "WARNING:tensorflow:Entity <bound method BatchNormalization.call of <tensorflow.python.layers.normalization.BatchNormalization object at 0x137b4c470>> could not be transformed and will be executed as-is. Please report this to the AutgoGraph team. When filing the bug, set the verbosity to 10 (on Linux, `export AUTOGRAPH_VERBOSITY=10`) and attach the full output. Cause: converting <bound method BatchNormalization.call of <tensorflow.python.layers.normalization.BatchNormalization object at 0x137b4c470>>: AssertionError: Bad argument number for Name: 3, expecting 4\n",
      "W0925 10:35:18.939895 4643411392 ag_logging.py:145] Entity <bound method BatchNormalization.call of <tensorflow.python.layers.normalization.BatchNormalization object at 0x137b4c470>> could not be transformed and will be executed as-is. Please report this to the AutgoGraph team. When filing the bug, set the verbosity to 10 (on Linux, `export AUTOGRAPH_VERBOSITY=10`) and attach the full output. Cause: converting <bound method BatchNormalization.call of <tensorflow.python.layers.normalization.BatchNormalization object at 0x137b4c470>>: AssertionError: Bad argument number for Name: 3, expecting 4\n",
      "WARNING:tensorflow:Entity <bound method Conv.call of <tensorflow.python.layers.convolutional.Conv2D object at 0x137c99cc0>> could not be transformed and will be executed as-is. Please report this to the AutgoGraph team. When filing the bug, set the verbosity to 10 (on Linux, `export AUTOGRAPH_VERBOSITY=10`) and attach the full output. Cause: converting <bound method Conv.call of <tensorflow.python.layers.convolutional.Conv2D object at 0x137c99cc0>>: AssertionError: Bad argument number for Name: 3, expecting 4\n",
      "W0925 10:35:19.025907 4643411392 ag_logging.py:145] Entity <bound method Conv.call of <tensorflow.python.layers.convolutional.Conv2D object at 0x137c99cc0>> could not be transformed and will be executed as-is. Please report this to the AutgoGraph team. When filing the bug, set the verbosity to 10 (on Linux, `export AUTOGRAPH_VERBOSITY=10`) and attach the full output. Cause: converting <bound method Conv.call of <tensorflow.python.layers.convolutional.Conv2D object at 0x137c99cc0>>: AssertionError: Bad argument number for Name: 3, expecting 4\n",
      "WARNING:tensorflow:Entity <bound method BatchNormalization.call of <tensorflow.python.layers.normalization.BatchNormalization object at 0x137c032b0>> could not be transformed and will be executed as-is. Please report this to the AutgoGraph team. When filing the bug, set the verbosity to 10 (on Linux, `export AUTOGRAPH_VERBOSITY=10`) and attach the full output. Cause: converting <bound method BatchNormalization.call of <tensorflow.python.layers.normalization.BatchNormalization object at 0x137c032b0>>: AssertionError: Bad argument number for Name: 3, expecting 4\n",
      "W0925 10:35:19.083806 4643411392 ag_logging.py:145] Entity <bound method BatchNormalization.call of <tensorflow.python.layers.normalization.BatchNormalization object at 0x137c032b0>> could not be transformed and will be executed as-is. Please report this to the AutgoGraph team. When filing the bug, set the verbosity to 10 (on Linux, `export AUTOGRAPH_VERBOSITY=10`) and attach the full output. Cause: converting <bound method BatchNormalization.call of <tensorflow.python.layers.normalization.BatchNormalization object at 0x137c032b0>>: AssertionError: Bad argument number for Name: 3, expecting 4\n"
     ]
    },
    {
     "name": "stdout",
     "output_type": "stream",
     "text": [
      "WARNING:tensorflow:Entity <bound method Conv.call of <tensorflow.python.layers.convolutional.Conv2D object at 0x137d20e48>> could not be transformed and will be executed as-is. Please report this to the AutgoGraph team. When filing the bug, set the verbosity to 10 (on Linux, `export AUTOGRAPH_VERBOSITY=10`) and attach the full output. Cause: converting <bound method Conv.call of <tensorflow.python.layers.convolutional.Conv2D object at 0x137d20e48>>: AssertionError: Bad argument number for Name: 3, expecting 4\n",
      "W0925 10:35:19.204926 4643411392 ag_logging.py:145] Entity <bound method Conv.call of <tensorflow.python.layers.convolutional.Conv2D object at 0x137d20e48>> could not be transformed and will be executed as-is. Please report this to the AutgoGraph team. When filing the bug, set the verbosity to 10 (on Linux, `export AUTOGRAPH_VERBOSITY=10`) and attach the full output. Cause: converting <bound method Conv.call of <tensorflow.python.layers.convolutional.Conv2D object at 0x137d20e48>>: AssertionError: Bad argument number for Name: 3, expecting 4\n",
      "WARNING:tensorflow:Entity <bound method BatchNormalization.call of <tensorflow.python.layers.normalization.BatchNormalization object at 0x137c03518>> could not be transformed and will be executed as-is. Please report this to the AutgoGraph team. When filing the bug, set the verbosity to 10 (on Linux, `export AUTOGRAPH_VERBOSITY=10`) and attach the full output. Cause: converting <bound method BatchNormalization.call of <tensorflow.python.layers.normalization.BatchNormalization object at 0x137c03518>>: AssertionError: Bad argument number for Name: 3, expecting 4\n",
      "W0925 10:35:19.268943 4643411392 ag_logging.py:145] Entity <bound method BatchNormalization.call of <tensorflow.python.layers.normalization.BatchNormalization object at 0x137c03518>> could not be transformed and will be executed as-is. Please report this to the AutgoGraph team. When filing the bug, set the verbosity to 10 (on Linux, `export AUTOGRAPH_VERBOSITY=10`) and attach the full output. Cause: converting <bound method BatchNormalization.call of <tensorflow.python.layers.normalization.BatchNormalization object at 0x137c03518>>: AssertionError: Bad argument number for Name: 3, expecting 4\n",
      "WARNING:tensorflow:Entity <bound method Conv.call of <tensorflow.python.layers.convolutional.Conv2D object at 0x137b01ac8>> could not be transformed and will be executed as-is. Please report this to the AutgoGraph team. When filing the bug, set the verbosity to 10 (on Linux, `export AUTOGRAPH_VERBOSITY=10`) and attach the full output. Cause: converting <bound method Conv.call of <tensorflow.python.layers.convolutional.Conv2D object at 0x137b01ac8>>: AssertionError: Bad argument number for Name: 3, expecting 4\n",
      "W0925 10:35:19.388851 4643411392 ag_logging.py:145] Entity <bound method Conv.call of <tensorflow.python.layers.convolutional.Conv2D object at 0x137b01ac8>> could not be transformed and will be executed as-is. Please report this to the AutgoGraph team. When filing the bug, set the verbosity to 10 (on Linux, `export AUTOGRAPH_VERBOSITY=10`) and attach the full output. Cause: converting <bound method Conv.call of <tensorflow.python.layers.convolutional.Conv2D object at 0x137b01ac8>>: AssertionError: Bad argument number for Name: 3, expecting 4\n",
      "WARNING:tensorflow:Entity <bound method BatchNormalization.call of <tensorflow.python.layers.normalization.BatchNormalization object at 0x137c40c50>> could not be transformed and will be executed as-is. Please report this to the AutgoGraph team. When filing the bug, set the verbosity to 10 (on Linux, `export AUTOGRAPH_VERBOSITY=10`) and attach the full output. Cause: converting <bound method BatchNormalization.call of <tensorflow.python.layers.normalization.BatchNormalization object at 0x137c40c50>>: AssertionError: Bad argument number for Name: 3, expecting 4\n",
      "W0925 10:35:19.456313 4643411392 ag_logging.py:145] Entity <bound method BatchNormalization.call of <tensorflow.python.layers.normalization.BatchNormalization object at 0x137c40c50>> could not be transformed and will be executed as-is. Please report this to the AutgoGraph team. When filing the bug, set the verbosity to 10 (on Linux, `export AUTOGRAPH_VERBOSITY=10`) and attach the full output. Cause: converting <bound method BatchNormalization.call of <tensorflow.python.layers.normalization.BatchNormalization object at 0x137c40c50>>: AssertionError: Bad argument number for Name: 3, expecting 4\n",
      "WARNING:tensorflow:Entity <bound method Conv.call of <tensorflow.python.layers.convolutional.Conv2D object at 0x137b01b70>> could not be transformed and will be executed as-is. Please report this to the AutgoGraph team. When filing the bug, set the verbosity to 10 (on Linux, `export AUTOGRAPH_VERBOSITY=10`) and attach the full output. Cause: converting <bound method Conv.call of <tensorflow.python.layers.convolutional.Conv2D object at 0x137b01b70>>: AssertionError: Bad argument number for Name: 3, expecting 4\n",
      "W0925 10:35:19.583703 4643411392 ag_logging.py:145] Entity <bound method Conv.call of <tensorflow.python.layers.convolutional.Conv2D object at 0x137b01b70>> could not be transformed and will be executed as-is. Please report this to the AutgoGraph team. When filing the bug, set the verbosity to 10 (on Linux, `export AUTOGRAPH_VERBOSITY=10`) and attach the full output. Cause: converting <bound method Conv.call of <tensorflow.python.layers.convolutional.Conv2D object at 0x137b01b70>>: AssertionError: Bad argument number for Name: 3, expecting 4\n",
      "WARNING:tensorflow:Entity <bound method BatchNormalization.call of <tensorflow.python.layers.normalization.BatchNormalization object at 0x137c994a8>> could not be transformed and will be executed as-is. Please report this to the AutgoGraph team. When filing the bug, set the verbosity to 10 (on Linux, `export AUTOGRAPH_VERBOSITY=10`) and attach the full output. Cause: converting <bound method BatchNormalization.call of <tensorflow.python.layers.normalization.BatchNormalization object at 0x137c994a8>>: AssertionError: Bad argument number for Name: 3, expecting 4\n",
      "W0925 10:35:19.638998 4643411392 ag_logging.py:145] Entity <bound method BatchNormalization.call of <tensorflow.python.layers.normalization.BatchNormalization object at 0x137c994a8>> could not be transformed and will be executed as-is. Please report this to the AutgoGraph team. When filing the bug, set the verbosity to 10 (on Linux, `export AUTOGRAPH_VERBOSITY=10`) and attach the full output. Cause: converting <bound method BatchNormalization.call of <tensorflow.python.layers.normalization.BatchNormalization object at 0x137c994a8>>: AssertionError: Bad argument number for Name: 3, expecting 4\n",
      "WARNING:tensorflow:Entity <bound method Conv.call of <tensorflow.python.layers.convolutional.Conv2D object at 0x137e5cbe0>> could not be transformed and will be executed as-is. Please report this to the AutgoGraph team. When filing the bug, set the verbosity to 10 (on Linux, `export AUTOGRAPH_VERBOSITY=10`) and attach the full output. Cause: converting <bound method Conv.call of <tensorflow.python.layers.convolutional.Conv2D object at 0x137e5cbe0>>: AssertionError: Bad argument number for Name: 3, expecting 4\n",
      "W0925 10:35:19.775336 4643411392 ag_logging.py:145] Entity <bound method Conv.call of <tensorflow.python.layers.convolutional.Conv2D object at 0x137e5cbe0>> could not be transformed and will be executed as-is. Please report this to the AutgoGraph team. When filing the bug, set the verbosity to 10 (on Linux, `export AUTOGRAPH_VERBOSITY=10`) and attach the full output. Cause: converting <bound method Conv.call of <tensorflow.python.layers.convolutional.Conv2D object at 0x137e5cbe0>>: AssertionError: Bad argument number for Name: 3, expecting 4\n",
      "WARNING:tensorflow:Entity <bound method BatchNormalization.call of <tensorflow.python.layers.normalization.BatchNormalization object at 0x137c99748>> could not be transformed and will be executed as-is. Please report this to the AutgoGraph team. When filing the bug, set the verbosity to 10 (on Linux, `export AUTOGRAPH_VERBOSITY=10`) and attach the full output. Cause: converting <bound method BatchNormalization.call of <tensorflow.python.layers.normalization.BatchNormalization object at 0x137c99748>>: AssertionError: Bad argument number for Name: 3, expecting 4\n",
      "W0925 10:35:19.975653 4643411392 ag_logging.py:145] Entity <bound method BatchNormalization.call of <tensorflow.python.layers.normalization.BatchNormalization object at 0x137c99748>> could not be transformed and will be executed as-is. Please report this to the AutgoGraph team. When filing the bug, set the verbosity to 10 (on Linux, `export AUTOGRAPH_VERBOSITY=10`) and attach the full output. Cause: converting <bound method BatchNormalization.call of <tensorflow.python.layers.normalization.BatchNormalization object at 0x137c99748>>: AssertionError: Bad argument number for Name: 3, expecting 4\n"
     ]
    },
    {
     "name": "stdout",
     "output_type": "stream",
     "text": [
      "WARNING:tensorflow:Entity <bound method Conv.call of <tensorflow.python.layers.convolutional.Conv2D object at 0x137b01ac8>> could not be transformed and will be executed as-is. Please report this to the AutgoGraph team. When filing the bug, set the verbosity to 10 (on Linux, `export AUTOGRAPH_VERBOSITY=10`) and attach the full output. Cause: converting <bound method Conv.call of <tensorflow.python.layers.convolutional.Conv2D object at 0x137b01ac8>>: AssertionError: Bad argument number for Name: 3, expecting 4\n",
      "W0925 10:35:20.099525 4643411392 ag_logging.py:145] Entity <bound method Conv.call of <tensorflow.python.layers.convolutional.Conv2D object at 0x137b01ac8>> could not be transformed and will be executed as-is. Please report this to the AutgoGraph team. When filing the bug, set the verbosity to 10 (on Linux, `export AUTOGRAPH_VERBOSITY=10`) and attach the full output. Cause: converting <bound method Conv.call of <tensorflow.python.layers.convolutional.Conv2D object at 0x137b01ac8>>: AssertionError: Bad argument number for Name: 3, expecting 4\n",
      "WARNING:tensorflow:Entity <bound method BatchNormalization.call of <tensorflow.python.layers.normalization.BatchNormalization object at 0x137e25668>> could not be transformed and will be executed as-is. Please report this to the AutgoGraph team. When filing the bug, set the verbosity to 10 (on Linux, `export AUTOGRAPH_VERBOSITY=10`) and attach the full output. Cause: converting <bound method BatchNormalization.call of <tensorflow.python.layers.normalization.BatchNormalization object at 0x137e25668>>: AssertionError: Bad argument number for Name: 3, expecting 4\n",
      "W0925 10:35:20.154762 4643411392 ag_logging.py:145] Entity <bound method BatchNormalization.call of <tensorflow.python.layers.normalization.BatchNormalization object at 0x137e25668>> could not be transformed and will be executed as-is. Please report this to the AutgoGraph team. When filing the bug, set the verbosity to 10 (on Linux, `export AUTOGRAPH_VERBOSITY=10`) and attach the full output. Cause: converting <bound method BatchNormalization.call of <tensorflow.python.layers.normalization.BatchNormalization object at 0x137e25668>>: AssertionError: Bad argument number for Name: 3, expecting 4\n",
      "WARNING:tensorflow:Entity <bound method Conv.call of <tensorflow.python.layers.convolutional.Conv2D object at 0x137b01d30>> could not be transformed and will be executed as-is. Please report this to the AutgoGraph team. When filing the bug, set the verbosity to 10 (on Linux, `export AUTOGRAPH_VERBOSITY=10`) and attach the full output. Cause: converting <bound method Conv.call of <tensorflow.python.layers.convolutional.Conv2D object at 0x137b01d30>>: AssertionError: Bad argument number for Name: 3, expecting 4\n",
      "W0925 10:35:20.284662 4643411392 ag_logging.py:145] Entity <bound method Conv.call of <tensorflow.python.layers.convolutional.Conv2D object at 0x137b01d30>> could not be transformed and will be executed as-is. Please report this to the AutgoGraph team. When filing the bug, set the verbosity to 10 (on Linux, `export AUTOGRAPH_VERBOSITY=10`) and attach the full output. Cause: converting <bound method Conv.call of <tensorflow.python.layers.convolutional.Conv2D object at 0x137b01d30>>: AssertionError: Bad argument number for Name: 3, expecting 4\n",
      "WARNING:tensorflow:Entity <bound method BatchNormalization.call of <tensorflow.python.layers.normalization.BatchNormalization object at 0x137e259e8>> could not be transformed and will be executed as-is. Please report this to the AutgoGraph team. When filing the bug, set the verbosity to 10 (on Linux, `export AUTOGRAPH_VERBOSITY=10`) and attach the full output. Cause: converting <bound method BatchNormalization.call of <tensorflow.python.layers.normalization.BatchNormalization object at 0x137e259e8>>: AssertionError: Bad argument number for Name: 3, expecting 4\n",
      "W0925 10:35:20.357342 4643411392 ag_logging.py:145] Entity <bound method BatchNormalization.call of <tensorflow.python.layers.normalization.BatchNormalization object at 0x137e259e8>> could not be transformed and will be executed as-is. Please report this to the AutgoGraph team. When filing the bug, set the verbosity to 10 (on Linux, `export AUTOGRAPH_VERBOSITY=10`) and attach the full output. Cause: converting <bound method BatchNormalization.call of <tensorflow.python.layers.normalization.BatchNormalization object at 0x137e259e8>>: AssertionError: Bad argument number for Name: 3, expecting 4\n",
      "WARNING:tensorflow:Entity <bound method Conv.call of <tensorflow.python.layers.convolutional.Conv2D object at 0x137e70f60>> could not be transformed and will be executed as-is. Please report this to the AutgoGraph team. When filing the bug, set the verbosity to 10 (on Linux, `export AUTOGRAPH_VERBOSITY=10`) and attach the full output. Cause: converting <bound method Conv.call of <tensorflow.python.layers.convolutional.Conv2D object at 0x137e70f60>>: AssertionError: Bad argument number for Name: 3, expecting 4\n",
      "W0925 10:35:20.465357 4643411392 ag_logging.py:145] Entity <bound method Conv.call of <tensorflow.python.layers.convolutional.Conv2D object at 0x137e70f60>> could not be transformed and will be executed as-is. Please report this to the AutgoGraph team. When filing the bug, set the verbosity to 10 (on Linux, `export AUTOGRAPH_VERBOSITY=10`) and attach the full output. Cause: converting <bound method Conv.call of <tensorflow.python.layers.convolutional.Conv2D object at 0x137e70f60>>: AssertionError: Bad argument number for Name: 3, expecting 4\n",
      "WARNING:tensorflow:Entity <bound method BatchNormalization.call of <tensorflow.python.layers.normalization.BatchNormalization object at 0x137e25b38>> could not be transformed and will be executed as-is. Please report this to the AutgoGraph team. When filing the bug, set the verbosity to 10 (on Linux, `export AUTOGRAPH_VERBOSITY=10`) and attach the full output. Cause: converting <bound method BatchNormalization.call of <tensorflow.python.layers.normalization.BatchNormalization object at 0x137e25b38>>: AssertionError: Bad argument number for Name: 3, expecting 4\n",
      "W0925 10:35:20.524967 4643411392 ag_logging.py:145] Entity <bound method BatchNormalization.call of <tensorflow.python.layers.normalization.BatchNormalization object at 0x137e25b38>> could not be transformed and will be executed as-is. Please report this to the AutgoGraph team. When filing the bug, set the verbosity to 10 (on Linux, `export AUTOGRAPH_VERBOSITY=10`) and attach the full output. Cause: converting <bound method BatchNormalization.call of <tensorflow.python.layers.normalization.BatchNormalization object at 0x137e25b38>>: AssertionError: Bad argument number for Name: 3, expecting 4\n",
      "WARNING:tensorflow:Entity <bound method Conv.call of <tensorflow.python.layers.convolutional.Conv2D object at 0x137808ac8>> could not be transformed and will be executed as-is. Please report this to the AutgoGraph team. When filing the bug, set the verbosity to 10 (on Linux, `export AUTOGRAPH_VERBOSITY=10`) and attach the full output. Cause: converting <bound method Conv.call of <tensorflow.python.layers.convolutional.Conv2D object at 0x137808ac8>>: AssertionError: Bad argument number for Name: 3, expecting 4\n",
      "W0925 10:35:20.649167 4643411392 ag_logging.py:145] Entity <bound method Conv.call of <tensorflow.python.layers.convolutional.Conv2D object at 0x137808ac8>> could not be transformed and will be executed as-is. Please report this to the AutgoGraph team. When filing the bug, set the verbosity to 10 (on Linux, `export AUTOGRAPH_VERBOSITY=10`) and attach the full output. Cause: converting <bound method Conv.call of <tensorflow.python.layers.convolutional.Conv2D object at 0x137808ac8>>: AssertionError: Bad argument number for Name: 3, expecting 4\n",
      "WARNING:tensorflow:Entity <bound method BatchNormalization.call of <tensorflow.python.layers.normalization.BatchNormalization object at 0x137e25d68>> could not be transformed and will be executed as-is. Please report this to the AutgoGraph team. When filing the bug, set the verbosity to 10 (on Linux, `export AUTOGRAPH_VERBOSITY=10`) and attach the full output. Cause: converting <bound method BatchNormalization.call of <tensorflow.python.layers.normalization.BatchNormalization object at 0x137e25d68>>: AssertionError: Bad argument number for Name: 3, expecting 4\n",
      "W0925 10:35:20.703385 4643411392 ag_logging.py:145] Entity <bound method BatchNormalization.call of <tensorflow.python.layers.normalization.BatchNormalization object at 0x137e25d68>> could not be transformed and will be executed as-is. Please report this to the AutgoGraph team. When filing the bug, set the verbosity to 10 (on Linux, `export AUTOGRAPH_VERBOSITY=10`) and attach the full output. Cause: converting <bound method BatchNormalization.call of <tensorflow.python.layers.normalization.BatchNormalization object at 0x137e25d68>>: AssertionError: Bad argument number for Name: 3, expecting 4\n"
     ]
    },
    {
     "name": "stdout",
     "output_type": "stream",
     "text": [
      "WARNING:tensorflow:Entity <bound method Conv.call of <tensorflow.python.layers.convolutional.Conv2D object at 0x13804a9b0>> could not be transformed and will be executed as-is. Please report this to the AutgoGraph team. When filing the bug, set the verbosity to 10 (on Linux, `export AUTOGRAPH_VERBOSITY=10`) and attach the full output. Cause: converting <bound method Conv.call of <tensorflow.python.layers.convolutional.Conv2D object at 0x13804a9b0>>: AssertionError: Bad argument number for Name: 3, expecting 4\n",
      "W0925 10:35:20.774206 4643411392 ag_logging.py:145] Entity <bound method Conv.call of <tensorflow.python.layers.convolutional.Conv2D object at 0x13804a9b0>> could not be transformed and will be executed as-is. Please report this to the AutgoGraph team. When filing the bug, set the verbosity to 10 (on Linux, `export AUTOGRAPH_VERBOSITY=10`) and attach the full output. Cause: converting <bound method Conv.call of <tensorflow.python.layers.convolutional.Conv2D object at 0x13804a9b0>>: AssertionError: Bad argument number for Name: 3, expecting 4\n",
      "WARNING:tensorflow:Entity <bound method BatchNormalization.call of <tensorflow.python.layers.normalization.BatchNormalization object at 0x137e25f98>> could not be transformed and will be executed as-is. Please report this to the AutgoGraph team. When filing the bug, set the verbosity to 10 (on Linux, `export AUTOGRAPH_VERBOSITY=10`) and attach the full output. Cause: converting <bound method BatchNormalization.call of <tensorflow.python.layers.normalization.BatchNormalization object at 0x137e25f98>>: AssertionError: Bad argument number for Name: 3, expecting 4\n",
      "W0925 10:35:20.798511 4643411392 ag_logging.py:145] Entity <bound method BatchNormalization.call of <tensorflow.python.layers.normalization.BatchNormalization object at 0x137e25f98>> could not be transformed and will be executed as-is. Please report this to the AutgoGraph team. When filing the bug, set the verbosity to 10 (on Linux, `export AUTOGRAPH_VERBOSITY=10`) and attach the full output. Cause: converting <bound method BatchNormalization.call of <tensorflow.python.layers.normalization.BatchNormalization object at 0x137e25f98>>: AssertionError: Bad argument number for Name: 3, expecting 4\n",
      "WARNING:tensorflow:Entity <bound method Conv.call of <tensorflow.python.layers.convolutional.Conv2D object at 0x138043208>> could not be transformed and will be executed as-is. Please report this to the AutgoGraph team. When filing the bug, set the verbosity to 10 (on Linux, `export AUTOGRAPH_VERBOSITY=10`) and attach the full output. Cause: converting <bound method Conv.call of <tensorflow.python.layers.convolutional.Conv2D object at 0x138043208>>: AssertionError: Bad argument number for Name: 3, expecting 4\n",
      "W0925 10:35:20.858930 4643411392 ag_logging.py:145] Entity <bound method Conv.call of <tensorflow.python.layers.convolutional.Conv2D object at 0x138043208>> could not be transformed and will be executed as-is. Please report this to the AutgoGraph team. When filing the bug, set the verbosity to 10 (on Linux, `export AUTOGRAPH_VERBOSITY=10`) and attach the full output. Cause: converting <bound method Conv.call of <tensorflow.python.layers.convolutional.Conv2D object at 0x138043208>>: AssertionError: Bad argument number for Name: 3, expecting 4\n",
      "WARNING:tensorflow:Entity <bound method BatchNormalization.call of <tensorflow.python.layers.normalization.BatchNormalization object at 0x137ee2ef0>> could not be transformed and will be executed as-is. Please report this to the AutgoGraph team. When filing the bug, set the verbosity to 10 (on Linux, `export AUTOGRAPH_VERBOSITY=10`) and attach the full output. Cause: converting <bound method BatchNormalization.call of <tensorflow.python.layers.normalization.BatchNormalization object at 0x137ee2ef0>>: AssertionError: Bad argument number for Name: 3, expecting 4\n",
      "W0925 10:35:20.892332 4643411392 ag_logging.py:145] Entity <bound method BatchNormalization.call of <tensorflow.python.layers.normalization.BatchNormalization object at 0x137ee2ef0>> could not be transformed and will be executed as-is. Please report this to the AutgoGraph team. When filing the bug, set the verbosity to 10 (on Linux, `export AUTOGRAPH_VERBOSITY=10`) and attach the full output. Cause: converting <bound method BatchNormalization.call of <tensorflow.python.layers.normalization.BatchNormalization object at 0x137ee2ef0>>: AssertionError: Bad argument number for Name: 3, expecting 4\n",
      "WARNING:tensorflow:Entity <bound method Conv.call of <tensorflow.python.layers.convolutional.Conv2D object at 0x1380c4dd8>> could not be transformed and will be executed as-is. Please report this to the AutgoGraph team. When filing the bug, set the verbosity to 10 (on Linux, `export AUTOGRAPH_VERBOSITY=10`) and attach the full output. Cause: converting <bound method Conv.call of <tensorflow.python.layers.convolutional.Conv2D object at 0x1380c4dd8>>: AssertionError: Bad argument number for Name: 3, expecting 4\n",
      "W0925 10:35:20.958775 4643411392 ag_logging.py:145] Entity <bound method Conv.call of <tensorflow.python.layers.convolutional.Conv2D object at 0x1380c4dd8>> could not be transformed and will be executed as-is. Please report this to the AutgoGraph team. When filing the bug, set the verbosity to 10 (on Linux, `export AUTOGRAPH_VERBOSITY=10`) and attach the full output. Cause: converting <bound method Conv.call of <tensorflow.python.layers.convolutional.Conv2D object at 0x1380c4dd8>>: AssertionError: Bad argument number for Name: 3, expecting 4\n",
      "WARNING:tensorflow:Entity <bound method BatchNormalization.call of <tensorflow.python.layers.normalization.BatchNormalization object at 0x1381134e0>> could not be transformed and will be executed as-is. Please report this to the AutgoGraph team. When filing the bug, set the verbosity to 10 (on Linux, `export AUTOGRAPH_VERBOSITY=10`) and attach the full output. Cause: converting <bound method BatchNormalization.call of <tensorflow.python.layers.normalization.BatchNormalization object at 0x1381134e0>>: AssertionError: Bad argument number for Name: 3, expecting 4\n",
      "W0925 10:35:20.985229 4643411392 ag_logging.py:145] Entity <bound method BatchNormalization.call of <tensorflow.python.layers.normalization.BatchNormalization object at 0x1381134e0>> could not be transformed and will be executed as-is. Please report this to the AutgoGraph team. When filing the bug, set the verbosity to 10 (on Linux, `export AUTOGRAPH_VERBOSITY=10`) and attach the full output. Cause: converting <bound method BatchNormalization.call of <tensorflow.python.layers.normalization.BatchNormalization object at 0x1381134e0>>: AssertionError: Bad argument number for Name: 3, expecting 4\n",
      "WARNING:tensorflow:Entity <bound method Conv.call of <tensorflow.python.layers.convolutional.Conv2D object at 0x137229d30>> could not be transformed and will be executed as-is. Please report this to the AutgoGraph team. When filing the bug, set the verbosity to 10 (on Linux, `export AUTOGRAPH_VERBOSITY=10`) and attach the full output. Cause: converting <bound method Conv.call of <tensorflow.python.layers.convolutional.Conv2D object at 0x137229d30>>: AssertionError: Bad argument number for Name: 3, expecting 4\n",
      "W0925 10:35:21.073940 4643411392 ag_logging.py:145] Entity <bound method Conv.call of <tensorflow.python.layers.convolutional.Conv2D object at 0x137229d30>> could not be transformed and will be executed as-is. Please report this to the AutgoGraph team. When filing the bug, set the verbosity to 10 (on Linux, `export AUTOGRAPH_VERBOSITY=10`) and attach the full output. Cause: converting <bound method Conv.call of <tensorflow.python.layers.convolutional.Conv2D object at 0x137229d30>>: AssertionError: Bad argument number for Name: 3, expecting 4\n",
      "WARNING:tensorflow:Entity <bound method BatchNormalization.call of <tensorflow.python.layers.normalization.BatchNormalization object at 0x1308834a8>> could not be transformed and will be executed as-is. Please report this to the AutgoGraph team. When filing the bug, set the verbosity to 10 (on Linux, `export AUTOGRAPH_VERBOSITY=10`) and attach the full output. Cause: converting <bound method BatchNormalization.call of <tensorflow.python.layers.normalization.BatchNormalization object at 0x1308834a8>>: AssertionError: Bad argument number for Name: 3, expecting 4\n",
      "W0925 10:35:21.125612 4643411392 ag_logging.py:145] Entity <bound method BatchNormalization.call of <tensorflow.python.layers.normalization.BatchNormalization object at 0x1308834a8>> could not be transformed and will be executed as-is. Please report this to the AutgoGraph team. When filing the bug, set the verbosity to 10 (on Linux, `export AUTOGRAPH_VERBOSITY=10`) and attach the full output. Cause: converting <bound method BatchNormalization.call of <tensorflow.python.layers.normalization.BatchNormalization object at 0x1308834a8>>: AssertionError: Bad argument number for Name: 3, expecting 4\n"
     ]
    },
    {
     "name": "stdout",
     "output_type": "stream",
     "text": [
      "WARNING:tensorflow:Entity <bound method Conv.call of <tensorflow.python.layers.convolutional.Conv2D object at 0x1380c4cc0>> could not be transformed and will be executed as-is. Please report this to the AutgoGraph team. When filing the bug, set the verbosity to 10 (on Linux, `export AUTOGRAPH_VERBOSITY=10`) and attach the full output. Cause: converting <bound method Conv.call of <tensorflow.python.layers.convolutional.Conv2D object at 0x1380c4cc0>>: AssertionError: Bad argument number for Name: 3, expecting 4\n",
      "W0925 10:35:21.232736 4643411392 ag_logging.py:145] Entity <bound method Conv.call of <tensorflow.python.layers.convolutional.Conv2D object at 0x1380c4cc0>> could not be transformed and will be executed as-is. Please report this to the AutgoGraph team. When filing the bug, set the verbosity to 10 (on Linux, `export AUTOGRAPH_VERBOSITY=10`) and attach the full output. Cause: converting <bound method Conv.call of <tensorflow.python.layers.convolutional.Conv2D object at 0x1380c4cc0>>: AssertionError: Bad argument number for Name: 3, expecting 4\n",
      "WARNING:tensorflow:Entity <bound method BatchNormalization.call of <tensorflow.python.layers.normalization.BatchNormalization object at 0x130883588>> could not be transformed and will be executed as-is. Please report this to the AutgoGraph team. When filing the bug, set the verbosity to 10 (on Linux, `export AUTOGRAPH_VERBOSITY=10`) and attach the full output. Cause: converting <bound method BatchNormalization.call of <tensorflow.python.layers.normalization.BatchNormalization object at 0x130883588>>: AssertionError: Bad argument number for Name: 3, expecting 4\n",
      "W0925 10:35:21.276026 4643411392 ag_logging.py:145] Entity <bound method BatchNormalization.call of <tensorflow.python.layers.normalization.BatchNormalization object at 0x130883588>> could not be transformed and will be executed as-is. Please report this to the AutgoGraph team. When filing the bug, set the verbosity to 10 (on Linux, `export AUTOGRAPH_VERBOSITY=10`) and attach the full output. Cause: converting <bound method BatchNormalization.call of <tensorflow.python.layers.normalization.BatchNormalization object at 0x130883588>>: AssertionError: Bad argument number for Name: 3, expecting 4\n",
      "WARNING:tensorflow:Entity <bound method Conv.call of <tensorflow.python.layers.convolutional.Conv2D object at 0x1380cd978>> could not be transformed and will be executed as-is. Please report this to the AutgoGraph team. When filing the bug, set the verbosity to 10 (on Linux, `export AUTOGRAPH_VERBOSITY=10`) and attach the full output. Cause: converting <bound method Conv.call of <tensorflow.python.layers.convolutional.Conv2D object at 0x1380cd978>>: AssertionError: Bad argument number for Name: 3, expecting 4\n",
      "W0925 10:35:21.375397 4643411392 ag_logging.py:145] Entity <bound method Conv.call of <tensorflow.python.layers.convolutional.Conv2D object at 0x1380cd978>> could not be transformed and will be executed as-is. Please report this to the AutgoGraph team. When filing the bug, set the verbosity to 10 (on Linux, `export AUTOGRAPH_VERBOSITY=10`) and attach the full output. Cause: converting <bound method Conv.call of <tensorflow.python.layers.convolutional.Conv2D object at 0x1380cd978>>: AssertionError: Bad argument number for Name: 3, expecting 4\n",
      "WARNING:tensorflow:Entity <bound method BatchNormalization.call of <tensorflow.python.layers.normalization.BatchNormalization object at 0x130883470>> could not be transformed and will be executed as-is. Please report this to the AutgoGraph team. When filing the bug, set the verbosity to 10 (on Linux, `export AUTOGRAPH_VERBOSITY=10`) and attach the full output. Cause: converting <bound method BatchNormalization.call of <tensorflow.python.layers.normalization.BatchNormalization object at 0x130883470>>: AssertionError: Bad argument number for Name: 3, expecting 4\n",
      "W0925 10:35:21.442255 4643411392 ag_logging.py:145] Entity <bound method BatchNormalization.call of <tensorflow.python.layers.normalization.BatchNormalization object at 0x130883470>> could not be transformed and will be executed as-is. Please report this to the AutgoGraph team. When filing the bug, set the verbosity to 10 (on Linux, `export AUTOGRAPH_VERBOSITY=10`) and attach the full output. Cause: converting <bound method BatchNormalization.call of <tensorflow.python.layers.normalization.BatchNormalization object at 0x130883470>>: AssertionError: Bad argument number for Name: 3, expecting 4\n",
      "WARNING:tensorflow:Entity <bound method Conv.call of <tensorflow.python.layers.convolutional.Conv2D object at 0x138113f60>> could not be transformed and will be executed as-is. Please report this to the AutgoGraph team. When filing the bug, set the verbosity to 10 (on Linux, `export AUTOGRAPH_VERBOSITY=10`) and attach the full output. Cause: converting <bound method Conv.call of <tensorflow.python.layers.convolutional.Conv2D object at 0x138113f60>>: AssertionError: Bad argument number for Name: 3, expecting 4\n",
      "W0925 10:35:21.576183 4643411392 ag_logging.py:145] Entity <bound method Conv.call of <tensorflow.python.layers.convolutional.Conv2D object at 0x138113f60>> could not be transformed and will be executed as-is. Please report this to the AutgoGraph team. When filing the bug, set the verbosity to 10 (on Linux, `export AUTOGRAPH_VERBOSITY=10`) and attach the full output. Cause: converting <bound method Conv.call of <tensorflow.python.layers.convolutional.Conv2D object at 0x138113f60>>: AssertionError: Bad argument number for Name: 3, expecting 4\n",
      "WARNING:tensorflow:Entity <bound method Conv.call of <tensorflow.python.layers.convolutional.Conv2D object at 0x138261c18>> could not be transformed and will be executed as-is. Please report this to the AutgoGraph team. When filing the bug, set the verbosity to 10 (on Linux, `export AUTOGRAPH_VERBOSITY=10`) and attach the full output. Cause: converting <bound method Conv.call of <tensorflow.python.layers.convolutional.Conv2D object at 0x138261c18>>: AssertionError: Bad argument number for Name: 3, expecting 4\n",
      "W0925 10:35:21.780947 4643411392 ag_logging.py:145] Entity <bound method Conv.call of <tensorflow.python.layers.convolutional.Conv2D object at 0x138261c18>> could not be transformed and will be executed as-is. Please report this to the AutgoGraph team. When filing the bug, set the verbosity to 10 (on Linux, `export AUTOGRAPH_VERBOSITY=10`) and attach the full output. Cause: converting <bound method Conv.call of <tensorflow.python.layers.convolutional.Conv2D object at 0x138261c18>>: AssertionError: Bad argument number for Name: 3, expecting 4\n",
      "WARNING:tensorflow:Entity <bound method BatchNormalization.call of <tensorflow.python.layers.normalization.BatchNormalization object at 0x1383a13c8>> could not be transformed and will be executed as-is. Please report this to the AutgoGraph team. When filing the bug, set the verbosity to 10 (on Linux, `export AUTOGRAPH_VERBOSITY=10`) and attach the full output. Cause: converting <bound method BatchNormalization.call of <tensorflow.python.layers.normalization.BatchNormalization object at 0x1383a13c8>>: AssertionError: Bad argument number for Name: 3, expecting 4\n",
      "W0925 10:35:21.845376 4643411392 ag_logging.py:145] Entity <bound method BatchNormalization.call of <tensorflow.python.layers.normalization.BatchNormalization object at 0x1383a13c8>> could not be transformed and will be executed as-is. Please report this to the AutgoGraph team. When filing the bug, set the verbosity to 10 (on Linux, `export AUTOGRAPH_VERBOSITY=10`) and attach the full output. Cause: converting <bound method BatchNormalization.call of <tensorflow.python.layers.normalization.BatchNormalization object at 0x1383a13c8>>: AssertionError: Bad argument number for Name: 3, expecting 4\n",
      "WARNING:tensorflow:From /Users/seungmin/Projects/OpenVINO/tensorflow-yolo-v3/yolo_v3.py:193: The name tf.image.resize_nearest_neighbor is deprecated. Please use tf.compat.v1.image.resize_nearest_neighbor instead.\n",
      "\n",
      "W0925 10:35:21.851188 4643411392 deprecation_wrapper.py:119] From /Users/seungmin/Projects/OpenVINO/tensorflow-yolo-v3/yolo_v3.py:193: The name tf.image.resize_nearest_neighbor is deprecated. Please use tf.compat.v1.image.resize_nearest_neighbor instead.\n",
      "\n"
     ]
    },
    {
     "name": "stdout",
     "output_type": "stream",
     "text": [
      "WARNING:tensorflow:Entity <bound method Conv.call of <tensorflow.python.layers.convolutional.Conv2D object at 0x13836e8d0>> could not be transformed and will be executed as-is. Please report this to the AutgoGraph team. When filing the bug, set the verbosity to 10 (on Linux, `export AUTOGRAPH_VERBOSITY=10`) and attach the full output. Cause: converting <bound method Conv.call of <tensorflow.python.layers.convolutional.Conv2D object at 0x13836e8d0>>: AssertionError: Bad argument number for Name: 3, expecting 4\n",
      "W0925 10:35:21.985697 4643411392 ag_logging.py:145] Entity <bound method Conv.call of <tensorflow.python.layers.convolutional.Conv2D object at 0x13836e8d0>> could not be transformed and will be executed as-is. Please report this to the AutgoGraph team. When filing the bug, set the verbosity to 10 (on Linux, `export AUTOGRAPH_VERBOSITY=10`) and attach the full output. Cause: converting <bound method Conv.call of <tensorflow.python.layers.convolutional.Conv2D object at 0x13836e8d0>>: AssertionError: Bad argument number for Name: 3, expecting 4\n",
      "WARNING:tensorflow:Entity <bound method BatchNormalization.call of <tensorflow.python.layers.normalization.BatchNormalization object at 0x138132f28>> could not be transformed and will be executed as-is. Please report this to the AutgoGraph team. When filing the bug, set the verbosity to 10 (on Linux, `export AUTOGRAPH_VERBOSITY=10`) and attach the full output. Cause: converting <bound method BatchNormalization.call of <tensorflow.python.layers.normalization.BatchNormalization object at 0x138132f28>>: AssertionError: Bad argument number for Name: 3, expecting 4\n",
      "W0925 10:35:22.047532 4643411392 ag_logging.py:145] Entity <bound method BatchNormalization.call of <tensorflow.python.layers.normalization.BatchNormalization object at 0x138132f28>> could not be transformed and will be executed as-is. Please report this to the AutgoGraph team. When filing the bug, set the verbosity to 10 (on Linux, `export AUTOGRAPH_VERBOSITY=10`) and attach the full output. Cause: converting <bound method BatchNormalization.call of <tensorflow.python.layers.normalization.BatchNormalization object at 0x138132f28>>: AssertionError: Bad argument number for Name: 3, expecting 4\n",
      "WARNING:tensorflow:Entity <bound method Conv.call of <tensorflow.python.layers.convolutional.Conv2D object at 0x1383a1fd0>> could not be transformed and will be executed as-is. Please report this to the AutgoGraph team. When filing the bug, set the verbosity to 10 (on Linux, `export AUTOGRAPH_VERBOSITY=10`) and attach the full output. Cause: converting <bound method Conv.call of <tensorflow.python.layers.convolutional.Conv2D object at 0x1383a1fd0>>: AssertionError: Bad argument number for Name: 3, expecting 4\n",
      "W0925 10:35:22.178576 4643411392 ag_logging.py:145] Entity <bound method Conv.call of <tensorflow.python.layers.convolutional.Conv2D object at 0x1383a1fd0>> could not be transformed and will be executed as-is. Please report this to the AutgoGraph team. When filing the bug, set the verbosity to 10 (on Linux, `export AUTOGRAPH_VERBOSITY=10`) and attach the full output. Cause: converting <bound method Conv.call of <tensorflow.python.layers.convolutional.Conv2D object at 0x1383a1fd0>>: AssertionError: Bad argument number for Name: 3, expecting 4\n",
      "WARNING:tensorflow:Entity <bound method BatchNormalization.call of <tensorflow.python.layers.normalization.BatchNormalization object at 0x13817bb00>> could not be transformed and will be executed as-is. Please report this to the AutgoGraph team. When filing the bug, set the verbosity to 10 (on Linux, `export AUTOGRAPH_VERBOSITY=10`) and attach the full output. Cause: converting <bound method BatchNormalization.call of <tensorflow.python.layers.normalization.BatchNormalization object at 0x13817bb00>>: AssertionError: Bad argument number for Name: 3, expecting 4\n",
      "W0925 10:35:22.234653 4643411392 ag_logging.py:145] Entity <bound method BatchNormalization.call of <tensorflow.python.layers.normalization.BatchNormalization object at 0x13817bb00>> could not be transformed and will be executed as-is. Please report this to the AutgoGraph team. When filing the bug, set the verbosity to 10 (on Linux, `export AUTOGRAPH_VERBOSITY=10`) and attach the full output. Cause: converting <bound method BatchNormalization.call of <tensorflow.python.layers.normalization.BatchNormalization object at 0x13817bb00>>: AssertionError: Bad argument number for Name: 3, expecting 4\n",
      "WARNING:tensorflow:Entity <bound method Conv.call of <tensorflow.python.layers.convolutional.Conv2D object at 0x1383f05f8>> could not be transformed and will be executed as-is. Please report this to the AutgoGraph team. When filing the bug, set the verbosity to 10 (on Linux, `export AUTOGRAPH_VERBOSITY=10`) and attach the full output. Cause: converting <bound method Conv.call of <tensorflow.python.layers.convolutional.Conv2D object at 0x1383f05f8>>: AssertionError: Bad argument number for Name: 3, expecting 4\n",
      "W0925 10:35:22.390609 4643411392 ag_logging.py:145] Entity <bound method Conv.call of <tensorflow.python.layers.convolutional.Conv2D object at 0x1383f05f8>> could not be transformed and will be executed as-is. Please report this to the AutgoGraph team. When filing the bug, set the verbosity to 10 (on Linux, `export AUTOGRAPH_VERBOSITY=10`) and attach the full output. Cause: converting <bound method Conv.call of <tensorflow.python.layers.convolutional.Conv2D object at 0x1383f05f8>>: AssertionError: Bad argument number for Name: 3, expecting 4\n",
      "WARNING:tensorflow:Entity <bound method BatchNormalization.call of <tensorflow.python.layers.normalization.BatchNormalization object at 0x1381eff98>> could not be transformed and will be executed as-is. Please report this to the AutgoGraph team. When filing the bug, set the verbosity to 10 (on Linux, `export AUTOGRAPH_VERBOSITY=10`) and attach the full output. Cause: converting <bound method BatchNormalization.call of <tensorflow.python.layers.normalization.BatchNormalization object at 0x1381eff98>>: AssertionError: Bad argument number for Name: 3, expecting 4\n",
      "W0925 10:35:22.451245 4643411392 ag_logging.py:145] Entity <bound method BatchNormalization.call of <tensorflow.python.layers.normalization.BatchNormalization object at 0x1381eff98>> could not be transformed and will be executed as-is. Please report this to the AutgoGraph team. When filing the bug, set the verbosity to 10 (on Linux, `export AUTOGRAPH_VERBOSITY=10`) and attach the full output. Cause: converting <bound method BatchNormalization.call of <tensorflow.python.layers.normalization.BatchNormalization object at 0x1381eff98>>: AssertionError: Bad argument number for Name: 3, expecting 4\n",
      "WARNING:tensorflow:Entity <bound method Conv.call of <tensorflow.python.layers.convolutional.Conv2D object at 0x13836ef28>> could not be transformed and will be executed as-is. Please report this to the AutgoGraph team. When filing the bug, set the verbosity to 10 (on Linux, `export AUTOGRAPH_VERBOSITY=10`) and attach the full output. Cause: converting <bound method Conv.call of <tensorflow.python.layers.convolutional.Conv2D object at 0x13836ef28>>: AssertionError: Bad argument number for Name: 3, expecting 4\n",
      "W0925 10:35:22.575923 4643411392 ag_logging.py:145] Entity <bound method Conv.call of <tensorflow.python.layers.convolutional.Conv2D object at 0x13836ef28>> could not be transformed and will be executed as-is. Please report this to the AutgoGraph team. When filing the bug, set the verbosity to 10 (on Linux, `export AUTOGRAPH_VERBOSITY=10`) and attach the full output. Cause: converting <bound method Conv.call of <tensorflow.python.layers.convolutional.Conv2D object at 0x13836ef28>>: AssertionError: Bad argument number for Name: 3, expecting 4\n",
      "WARNING:tensorflow:Entity <bound method BatchNormalization.call of <tensorflow.python.layers.normalization.BatchNormalization object at 0x1382d2ef0>> could not be transformed and will be executed as-is. Please report this to the AutgoGraph team. When filing the bug, set the verbosity to 10 (on Linux, `export AUTOGRAPH_VERBOSITY=10`) and attach the full output. Cause: converting <bound method BatchNormalization.call of <tensorflow.python.layers.normalization.BatchNormalization object at 0x1382d2ef0>>: AssertionError: Bad argument number for Name: 3, expecting 4\n",
      "W0925 10:35:22.637809 4643411392 ag_logging.py:145] Entity <bound method BatchNormalization.call of <tensorflow.python.layers.normalization.BatchNormalization object at 0x1382d2ef0>> could not be transformed and will be executed as-is. Please report this to the AutgoGraph team. When filing the bug, set the verbosity to 10 (on Linux, `export AUTOGRAPH_VERBOSITY=10`) and attach the full output. Cause: converting <bound method BatchNormalization.call of <tensorflow.python.layers.normalization.BatchNormalization object at 0x1382d2ef0>>: AssertionError: Bad argument number for Name: 3, expecting 4\n"
     ]
    },
    {
     "name": "stdout",
     "output_type": "stream",
     "text": [
      "WARNING:tensorflow:Entity <bound method Conv.call of <tensorflow.python.layers.convolutional.Conv2D object at 0x1383f05f8>> could not be transformed and will be executed as-is. Please report this to the AutgoGraph team. When filing the bug, set the verbosity to 10 (on Linux, `export AUTOGRAPH_VERBOSITY=10`) and attach the full output. Cause: converting <bound method Conv.call of <tensorflow.python.layers.convolutional.Conv2D object at 0x1383f05f8>>: AssertionError: Bad argument number for Name: 3, expecting 4\n",
      "W0925 10:35:22.762271 4643411392 ag_logging.py:145] Entity <bound method Conv.call of <tensorflow.python.layers.convolutional.Conv2D object at 0x1383f05f8>> could not be transformed and will be executed as-is. Please report this to the AutgoGraph team. When filing the bug, set the verbosity to 10 (on Linux, `export AUTOGRAPH_VERBOSITY=10`) and attach the full output. Cause: converting <bound method Conv.call of <tensorflow.python.layers.convolutional.Conv2D object at 0x1383f05f8>>: AssertionError: Bad argument number for Name: 3, expecting 4\n",
      "WARNING:tensorflow:Entity <bound method BatchNormalization.call of <tensorflow.python.layers.normalization.BatchNormalization object at 0x1382ad668>> could not be transformed and will be executed as-is. Please report this to the AutgoGraph team. When filing the bug, set the verbosity to 10 (on Linux, `export AUTOGRAPH_VERBOSITY=10`) and attach the full output. Cause: converting <bound method BatchNormalization.call of <tensorflow.python.layers.normalization.BatchNormalization object at 0x1382ad668>>: AssertionError: Bad argument number for Name: 3, expecting 4\n",
      "W0925 10:35:22.820060 4643411392 ag_logging.py:145] Entity <bound method BatchNormalization.call of <tensorflow.python.layers.normalization.BatchNormalization object at 0x1382ad668>> could not be transformed and will be executed as-is. Please report this to the AutgoGraph team. When filing the bug, set the verbosity to 10 (on Linux, `export AUTOGRAPH_VERBOSITY=10`) and attach the full output. Cause: converting <bound method BatchNormalization.call of <tensorflow.python.layers.normalization.BatchNormalization object at 0x1382ad668>>: AssertionError: Bad argument number for Name: 3, expecting 4\n",
      "WARNING:tensorflow:Entity <bound method Conv.call of <tensorflow.python.layers.convolutional.Conv2D object at 0x1383a1940>> could not be transformed and will be executed as-is. Please report this to the AutgoGraph team. When filing the bug, set the verbosity to 10 (on Linux, `export AUTOGRAPH_VERBOSITY=10`) and attach the full output. Cause: converting <bound method Conv.call of <tensorflow.python.layers.convolutional.Conv2D object at 0x1383a1940>>: AssertionError: Bad argument number for Name: 3, expecting 4\n",
      "W0925 10:35:22.957378 4643411392 ag_logging.py:145] Entity <bound method Conv.call of <tensorflow.python.layers.convolutional.Conv2D object at 0x1383a1940>> could not be transformed and will be executed as-is. Please report this to the AutgoGraph team. When filing the bug, set the verbosity to 10 (on Linux, `export AUTOGRAPH_VERBOSITY=10`) and attach the full output. Cause: converting <bound method Conv.call of <tensorflow.python.layers.convolutional.Conv2D object at 0x1383a1940>>: AssertionError: Bad argument number for Name: 3, expecting 4\n",
      "WARNING:tensorflow:Entity <bound method BatchNormalization.call of <tensorflow.python.layers.normalization.BatchNormalization object at 0x1382ad668>> could not be transformed and will be executed as-is. Please report this to the AutgoGraph team. When filing the bug, set the verbosity to 10 (on Linux, `export AUTOGRAPH_VERBOSITY=10`) and attach the full output. Cause: converting <bound method BatchNormalization.call of <tensorflow.python.layers.normalization.BatchNormalization object at 0x1382ad668>>: AssertionError: Bad argument number for Name: 3, expecting 4\n",
      "W0925 10:35:23.025242 4643411392 ag_logging.py:145] Entity <bound method BatchNormalization.call of <tensorflow.python.layers.normalization.BatchNormalization object at 0x1382ad668>> could not be transformed and will be executed as-is. Please report this to the AutgoGraph team. When filing the bug, set the verbosity to 10 (on Linux, `export AUTOGRAPH_VERBOSITY=10`) and attach the full output. Cause: converting <bound method BatchNormalization.call of <tensorflow.python.layers.normalization.BatchNormalization object at 0x1382ad668>>: AssertionError: Bad argument number for Name: 3, expecting 4\n",
      "WARNING:tensorflow:Entity <bound method Conv.call of <tensorflow.python.layers.convolutional.Conv2D object at 0x138051e80>> could not be transformed and will be executed as-is. Please report this to the AutgoGraph team. When filing the bug, set the verbosity to 10 (on Linux, `export AUTOGRAPH_VERBOSITY=10`) and attach the full output. Cause: converting <bound method Conv.call of <tensorflow.python.layers.convolutional.Conv2D object at 0x138051e80>>: AssertionError: Bad argument number for Name: 3, expecting 4\n",
      "W0925 10:35:23.152901 4643411392 ag_logging.py:145] Entity <bound method Conv.call of <tensorflow.python.layers.convolutional.Conv2D object at 0x138051e80>> could not be transformed and will be executed as-is. Please report this to the AutgoGraph team. When filing the bug, set the verbosity to 10 (on Linux, `export AUTOGRAPH_VERBOSITY=10`) and attach the full output. Cause: converting <bound method Conv.call of <tensorflow.python.layers.convolutional.Conv2D object at 0x138051e80>>: AssertionError: Bad argument number for Name: 3, expecting 4\n",
      "WARNING:tensorflow:Entity <bound method Conv.call of <tensorflow.python.layers.convolutional.Conv2D object at 0x13840cac8>> could not be transformed and will be executed as-is. Please report this to the AutgoGraph team. When filing the bug, set the verbosity to 10 (on Linux, `export AUTOGRAPH_VERBOSITY=10`) and attach the full output. Cause: converting <bound method Conv.call of <tensorflow.python.layers.convolutional.Conv2D object at 0x13840cac8>>: AssertionError: Bad argument number for Name: 3, expecting 4\n",
      "W0925 10:35:23.341013 4643411392 ag_logging.py:145] Entity <bound method Conv.call of <tensorflow.python.layers.convolutional.Conv2D object at 0x13840cac8>> could not be transformed and will be executed as-is. Please report this to the AutgoGraph team. When filing the bug, set the verbosity to 10 (on Linux, `export AUTOGRAPH_VERBOSITY=10`) and attach the full output. Cause: converting <bound method Conv.call of <tensorflow.python.layers.convolutional.Conv2D object at 0x13840cac8>>: AssertionError: Bad argument number for Name: 3, expecting 4\n",
      "WARNING:tensorflow:Entity <bound method BatchNormalization.call of <tensorflow.python.layers.normalization.BatchNormalization object at 0x1385f79e8>> could not be transformed and will be executed as-is. Please report this to the AutgoGraph team. When filing the bug, set the verbosity to 10 (on Linux, `export AUTOGRAPH_VERBOSITY=10`) and attach the full output. Cause: converting <bound method BatchNormalization.call of <tensorflow.python.layers.normalization.BatchNormalization object at 0x1385f79e8>>: AssertionError: Bad argument number for Name: 3, expecting 4\n",
      "W0925 10:35:23.395850 4643411392 ag_logging.py:145] Entity <bound method BatchNormalization.call of <tensorflow.python.layers.normalization.BatchNormalization object at 0x1385f79e8>> could not be transformed and will be executed as-is. Please report this to the AutgoGraph team. When filing the bug, set the verbosity to 10 (on Linux, `export AUTOGRAPH_VERBOSITY=10`) and attach the full output. Cause: converting <bound method BatchNormalization.call of <tensorflow.python.layers.normalization.BatchNormalization object at 0x1385f79e8>>: AssertionError: Bad argument number for Name: 3, expecting 4\n",
      "WARNING:tensorflow:Entity <bound method Conv.call of <tensorflow.python.layers.convolutional.Conv2D object at 0x1385f7e80>> could not be transformed and will be executed as-is. Please report this to the AutgoGraph team. When filing the bug, set the verbosity to 10 (on Linux, `export AUTOGRAPH_VERBOSITY=10`) and attach the full output. Cause: converting <bound method Conv.call of <tensorflow.python.layers.convolutional.Conv2D object at 0x1385f7e80>>: AssertionError: Bad argument number for Name: 3, expecting 4\n",
      "W0925 10:35:23.518733 4643411392 ag_logging.py:145] Entity <bound method Conv.call of <tensorflow.python.layers.convolutional.Conv2D object at 0x1385f7e80>> could not be transformed and will be executed as-is. Please report this to the AutgoGraph team. When filing the bug, set the verbosity to 10 (on Linux, `export AUTOGRAPH_VERBOSITY=10`) and attach the full output. Cause: converting <bound method Conv.call of <tensorflow.python.layers.convolutional.Conv2D object at 0x1385f7e80>>: AssertionError: Bad argument number for Name: 3, expecting 4\n"
     ]
    },
    {
     "name": "stdout",
     "output_type": "stream",
     "text": [
      "WARNING:tensorflow:Entity <bound method BatchNormalization.call of <tensorflow.python.layers.normalization.BatchNormalization object at 0x1383b99b0>> could not be transformed and will be executed as-is. Please report this to the AutgoGraph team. When filing the bug, set the verbosity to 10 (on Linux, `export AUTOGRAPH_VERBOSITY=10`) and attach the full output. Cause: converting <bound method BatchNormalization.call of <tensorflow.python.layers.normalization.BatchNormalization object at 0x1383b99b0>>: AssertionError: Bad argument number for Name: 3, expecting 4\n",
      "W0925 10:35:23.579498 4643411392 ag_logging.py:145] Entity <bound method BatchNormalization.call of <tensorflow.python.layers.normalization.BatchNormalization object at 0x1383b99b0>> could not be transformed and will be executed as-is. Please report this to the AutgoGraph team. When filing the bug, set the verbosity to 10 (on Linux, `export AUTOGRAPH_VERBOSITY=10`) and attach the full output. Cause: converting <bound method BatchNormalization.call of <tensorflow.python.layers.normalization.BatchNormalization object at 0x1383b99b0>>: AssertionError: Bad argument number for Name: 3, expecting 4\n",
      "WARNING:tensorflow:Entity <bound method Conv.call of <tensorflow.python.layers.convolutional.Conv2D object at 0x1385360f0>> could not be transformed and will be executed as-is. Please report this to the AutgoGraph team. When filing the bug, set the verbosity to 10 (on Linux, `export AUTOGRAPH_VERBOSITY=10`) and attach the full output. Cause: converting <bound method Conv.call of <tensorflow.python.layers.convolutional.Conv2D object at 0x1385360f0>>: AssertionError: Bad argument number for Name: 3, expecting 4\n",
      "W0925 10:35:23.725626 4643411392 ag_logging.py:145] Entity <bound method Conv.call of <tensorflow.python.layers.convolutional.Conv2D object at 0x1385360f0>> could not be transformed and will be executed as-is. Please report this to the AutgoGraph team. When filing the bug, set the verbosity to 10 (on Linux, `export AUTOGRAPH_VERBOSITY=10`) and attach the full output. Cause: converting <bound method Conv.call of <tensorflow.python.layers.convolutional.Conv2D object at 0x1385360f0>>: AssertionError: Bad argument number for Name: 3, expecting 4\n",
      "WARNING:tensorflow:Entity <bound method BatchNormalization.call of <tensorflow.python.layers.normalization.BatchNormalization object at 0x13840ccc0>> could not be transformed and will be executed as-is. Please report this to the AutgoGraph team. When filing the bug, set the verbosity to 10 (on Linux, `export AUTOGRAPH_VERBOSITY=10`) and attach the full output. Cause: converting <bound method BatchNormalization.call of <tensorflow.python.layers.normalization.BatchNormalization object at 0x13840ccc0>>: AssertionError: Bad argument number for Name: 3, expecting 4\n",
      "W0925 10:35:23.779918 4643411392 ag_logging.py:145] Entity <bound method BatchNormalization.call of <tensorflow.python.layers.normalization.BatchNormalization object at 0x13840ccc0>> could not be transformed and will be executed as-is. Please report this to the AutgoGraph team. When filing the bug, set the verbosity to 10 (on Linux, `export AUTOGRAPH_VERBOSITY=10`) and attach the full output. Cause: converting <bound method BatchNormalization.call of <tensorflow.python.layers.normalization.BatchNormalization object at 0x13840ccc0>>: AssertionError: Bad argument number for Name: 3, expecting 4\n",
      "WARNING:tensorflow:Entity <bound method Conv.call of <tensorflow.python.layers.convolutional.Conv2D object at 0x137229d30>> could not be transformed and will be executed as-is. Please report this to the AutgoGraph team. When filing the bug, set the verbosity to 10 (on Linux, `export AUTOGRAPH_VERBOSITY=10`) and attach the full output. Cause: converting <bound method Conv.call of <tensorflow.python.layers.convolutional.Conv2D object at 0x137229d30>>: AssertionError: Bad argument number for Name: 3, expecting 4\n",
      "W0925 10:35:23.919034 4643411392 ag_logging.py:145] Entity <bound method Conv.call of <tensorflow.python.layers.convolutional.Conv2D object at 0x137229d30>> could not be transformed and will be executed as-is. Please report this to the AutgoGraph team. When filing the bug, set the verbosity to 10 (on Linux, `export AUTOGRAPH_VERBOSITY=10`) and attach the full output. Cause: converting <bound method Conv.call of <tensorflow.python.layers.convolutional.Conv2D object at 0x137229d30>>: AssertionError: Bad argument number for Name: 3, expecting 4\n",
      "WARNING:tensorflow:Entity <bound method BatchNormalization.call of <tensorflow.python.layers.normalization.BatchNormalization object at 0x1384550b8>> could not be transformed and will be executed as-is. Please report this to the AutgoGraph team. When filing the bug, set the verbosity to 10 (on Linux, `export AUTOGRAPH_VERBOSITY=10`) and attach the full output. Cause: converting <bound method BatchNormalization.call of <tensorflow.python.layers.normalization.BatchNormalization object at 0x1384550b8>>: AssertionError: Bad argument number for Name: 3, expecting 4\n",
      "W0925 10:35:23.979351 4643411392 ag_logging.py:145] Entity <bound method BatchNormalization.call of <tensorflow.python.layers.normalization.BatchNormalization object at 0x1384550b8>> could not be transformed and will be executed as-is. Please report this to the AutgoGraph team. When filing the bug, set the verbosity to 10 (on Linux, `export AUTOGRAPH_VERBOSITY=10`) and attach the full output. Cause: converting <bound method BatchNormalization.call of <tensorflow.python.layers.normalization.BatchNormalization object at 0x1384550b8>>: AssertionError: Bad argument number for Name: 3, expecting 4\n",
      "WARNING:tensorflow:Entity <bound method Conv.call of <tensorflow.python.layers.convolutional.Conv2D object at 0x1385f7a20>> could not be transformed and will be executed as-is. Please report this to the AutgoGraph team. When filing the bug, set the verbosity to 10 (on Linux, `export AUTOGRAPH_VERBOSITY=10`) and attach the full output. Cause: converting <bound method Conv.call of <tensorflow.python.layers.convolutional.Conv2D object at 0x1385f7a20>>: AssertionError: Bad argument number for Name: 3, expecting 4\n",
      "W0925 10:35:24.113998 4643411392 ag_logging.py:145] Entity <bound method Conv.call of <tensorflow.python.layers.convolutional.Conv2D object at 0x1385f7a20>> could not be transformed and will be executed as-is. Please report this to the AutgoGraph team. When filing the bug, set the verbosity to 10 (on Linux, `export AUTOGRAPH_VERBOSITY=10`) and attach the full output. Cause: converting <bound method Conv.call of <tensorflow.python.layers.convolutional.Conv2D object at 0x1385f7a20>>: AssertionError: Bad argument number for Name: 3, expecting 4\n",
      "WARNING:tensorflow:Entity <bound method BatchNormalization.call of <tensorflow.python.layers.normalization.BatchNormalization object at 0x1384e4898>> could not be transformed and will be executed as-is. Please report this to the AutgoGraph team. When filing the bug, set the verbosity to 10 (on Linux, `export AUTOGRAPH_VERBOSITY=10`) and attach the full output. Cause: converting <bound method BatchNormalization.call of <tensorflow.python.layers.normalization.BatchNormalization object at 0x1384e4898>>: AssertionError: Bad argument number for Name: 3, expecting 4\n",
      "W0925 10:35:24.180786 4643411392 ag_logging.py:145] Entity <bound method BatchNormalization.call of <tensorflow.python.layers.normalization.BatchNormalization object at 0x1384e4898>> could not be transformed and will be executed as-is. Please report this to the AutgoGraph team. When filing the bug, set the verbosity to 10 (on Linux, `export AUTOGRAPH_VERBOSITY=10`) and attach the full output. Cause: converting <bound method BatchNormalization.call of <tensorflow.python.layers.normalization.BatchNormalization object at 0x1384e4898>>: AssertionError: Bad argument number for Name: 3, expecting 4\n",
      "WARNING:tensorflow:Entity <bound method Conv.call of <tensorflow.python.layers.convolutional.Conv2D object at 0x1385e6d68>> could not be transformed and will be executed as-is. Please report this to the AutgoGraph team. When filing the bug, set the verbosity to 10 (on Linux, `export AUTOGRAPH_VERBOSITY=10`) and attach the full output. Cause: converting <bound method Conv.call of <tensorflow.python.layers.convolutional.Conv2D object at 0x1385e6d68>>: AssertionError: Bad argument number for Name: 3, expecting 4\n",
      "W0925 10:35:24.318590 4643411392 ag_logging.py:145] Entity <bound method Conv.call of <tensorflow.python.layers.convolutional.Conv2D object at 0x1385e6d68>> could not be transformed and will be executed as-is. Please report this to the AutgoGraph team. When filing the bug, set the verbosity to 10 (on Linux, `export AUTOGRAPH_VERBOSITY=10`) and attach the full output. Cause: converting <bound method Conv.call of <tensorflow.python.layers.convolutional.Conv2D object at 0x1385e6d68>>: AssertionError: Bad argument number for Name: 3, expecting 4\n"
     ]
    },
    {
     "name": "stdout",
     "output_type": "stream",
     "text": [
      "WARNING:tensorflow:Entity <bound method BatchNormalization.call of <tensorflow.python.layers.normalization.BatchNormalization object at 0x1384e4a20>> could not be transformed and will be executed as-is. Please report this to the AutgoGraph team. When filing the bug, set the verbosity to 10 (on Linux, `export AUTOGRAPH_VERBOSITY=10`) and attach the full output. Cause: converting <bound method BatchNormalization.call of <tensorflow.python.layers.normalization.BatchNormalization object at 0x1384e4a20>>: AssertionError: Bad argument number for Name: 3, expecting 4\n",
      "W0925 10:35:24.374030 4643411392 ag_logging.py:145] Entity <bound method BatchNormalization.call of <tensorflow.python.layers.normalization.BatchNormalization object at 0x1384e4a20>> could not be transformed and will be executed as-is. Please report this to the AutgoGraph team. When filing the bug, set the verbosity to 10 (on Linux, `export AUTOGRAPH_VERBOSITY=10`) and attach the full output. Cause: converting <bound method BatchNormalization.call of <tensorflow.python.layers.normalization.BatchNormalization object at 0x1384e4a20>>: AssertionError: Bad argument number for Name: 3, expecting 4\n",
      "WARNING:tensorflow:Entity <bound method Conv.call of <tensorflow.python.layers.convolutional.Conv2D object at 0x1385fe438>> could not be transformed and will be executed as-is. Please report this to the AutgoGraph team. When filing the bug, set the verbosity to 10 (on Linux, `export AUTOGRAPH_VERBOSITY=10`) and attach the full output. Cause: converting <bound method Conv.call of <tensorflow.python.layers.convolutional.Conv2D object at 0x1385fe438>>: AssertionError: Bad argument number for Name: 3, expecting 4\n",
      "W0925 10:35:24.511453 4643411392 ag_logging.py:145] Entity <bound method Conv.call of <tensorflow.python.layers.convolutional.Conv2D object at 0x1385fe438>> could not be transformed and will be executed as-is. Please report this to the AutgoGraph team. When filing the bug, set the verbosity to 10 (on Linux, `export AUTOGRAPH_VERBOSITY=10`) and attach the full output. Cause: converting <bound method Conv.call of <tensorflow.python.layers.convolutional.Conv2D object at 0x1385fe438>>: AssertionError: Bad argument number for Name: 3, expecting 4\n",
      "WARNING:tensorflow:Entity <bound method BatchNormalization.call of <tensorflow.python.layers.normalization.BatchNormalization object at 0x1384e4a90>> could not be transformed and will be executed as-is. Please report this to the AutgoGraph team. When filing the bug, set the verbosity to 10 (on Linux, `export AUTOGRAPH_VERBOSITY=10`) and attach the full output. Cause: converting <bound method BatchNormalization.call of <tensorflow.python.layers.normalization.BatchNormalization object at 0x1384e4a90>>: AssertionError: Bad argument number for Name: 3, expecting 4\n",
      "W0925 10:35:24.571320 4643411392 ag_logging.py:145] Entity <bound method BatchNormalization.call of <tensorflow.python.layers.normalization.BatchNormalization object at 0x1384e4a90>> could not be transformed and will be executed as-is. Please report this to the AutgoGraph team. When filing the bug, set the verbosity to 10 (on Linux, `export AUTOGRAPH_VERBOSITY=10`) and attach the full output. Cause: converting <bound method BatchNormalization.call of <tensorflow.python.layers.normalization.BatchNormalization object at 0x1384e4a90>>: AssertionError: Bad argument number for Name: 3, expecting 4\n",
      "WARNING:tensorflow:Entity <bound method Conv.call of <tensorflow.python.layers.convolutional.Conv2D object at 0x1386067b8>> could not be transformed and will be executed as-is. Please report this to the AutgoGraph team. When filing the bug, set the verbosity to 10 (on Linux, `export AUTOGRAPH_VERBOSITY=10`) and attach the full output. Cause: converting <bound method Conv.call of <tensorflow.python.layers.convolutional.Conv2D object at 0x1386067b8>>: AssertionError: Bad argument number for Name: 3, expecting 4\n",
      "W0925 10:35:24.717626 4643411392 ag_logging.py:145] Entity <bound method Conv.call of <tensorflow.python.layers.convolutional.Conv2D object at 0x1386067b8>> could not be transformed and will be executed as-is. Please report this to the AutgoGraph team. When filing the bug, set the verbosity to 10 (on Linux, `export AUTOGRAPH_VERBOSITY=10`) and attach the full output. Cause: converting <bound method Conv.call of <tensorflow.python.layers.convolutional.Conv2D object at 0x1386067b8>>: AssertionError: Bad argument number for Name: 3, expecting 4\n",
      "WARNING:tensorflow:From convert_weights_pb.py:46: The name tf.global_variables is deprecated. Please use tf.compat.v1.global_variables instead.\n",
      "\n",
      "W0925 10:35:24.788167 4643411392 deprecation_wrapper.py:119] From convert_weights_pb.py:46: The name tf.global_variables is deprecated. Please use tf.compat.v1.global_variables instead.\n",
      "\n",
      "WARNING:tensorflow:From /Users/seungmin/Projects/OpenVINO/tensorflow-yolo-v3/utils.py:93: The name tf.assign is deprecated. Please use tf.compat.v1.assign instead.\n",
      "\n",
      "W0925 10:35:24.989092 4643411392 deprecation_wrapper.py:119] From /Users/seungmin/Projects/OpenVINO/tensorflow-yolo-v3/utils.py:93: The name tf.assign is deprecated. Please use tf.compat.v1.assign instead.\n",
      "\n",
      "WARNING:tensorflow:From convert_weights_pb.py:51: The name tf.Session is deprecated. Please use tf.compat.v1.Session instead.\n",
      "\n",
      "W0925 10:35:29.006145 4643411392 deprecation_wrapper.py:119] From convert_weights_pb.py:51: The name tf.Session is deprecated. Please use tf.compat.v1.Session instead.\n",
      "\n",
      "2019-09-25 10:35:29.009078: I tensorflow/core/platform/cpu_feature_guard.cc:142] Your CPU supports instructions that this TensorFlow binary was not compiled to use: AVX2 FMA\n",
      "WARNING:tensorflow:From /Users/seungmin/Projects/OpenVINO/tensorflow-yolo-v3/utils.py:53: convert_variables_to_constants (from tensorflow.python.framework.graph_util_impl) is deprecated and will be removed in a future version.\n",
      "Instructions for updating:\n",
      "Use `tf.compat.v1.graph_util.convert_variables_to_constants`\n",
      "W0925 10:35:47.091320 4643411392 deprecation.py:323] From /Users/seungmin/Projects/OpenVINO/tensorflow-yolo-v3/utils.py:53: convert_variables_to_constants (from tensorflow.python.framework.graph_util_impl) is deprecated and will be removed in a future version.\n",
      "Instructions for updating:\n",
      "Use `tf.compat.v1.graph_util.convert_variables_to_constants`\n",
      "WARNING:tensorflow:From /Users/seungmin/anaconda3/lib/python3.7/site-packages/tensorflow/python/framework/graph_util_impl.py:270: extract_sub_graph (from tensorflow.python.framework.graph_util_impl) is deprecated and will be removed in a future version.\n",
      "Instructions for updating:\n",
      "Use `tf.compat.v1.graph_util.extract_sub_graph`\n",
      "W0925 10:35:47.092212 4643411392 deprecation.py:323] From /Users/seungmin/anaconda3/lib/python3.7/site-packages/tensorflow/python/framework/graph_util_impl.py:270: extract_sub_graph (from tensorflow.python.framework.graph_util_impl) is deprecated and will be removed in a future version.\n",
      "Instructions for updating:\n",
      "Use `tf.compat.v1.graph_util.extract_sub_graph`\n",
      "INFO:tensorflow:Froze 366 variables.\n",
      "I0925 10:35:48.899751 4643411392 graph_util_impl.py:311] Froze 366 variables.\n",
      "INFO:tensorflow:Converted 366 variables to const ops.\n",
      "I0925 10:35:49.897339 4643411392 graph_util_impl.py:364] Converted 366 variables to const ops.\n",
      "WARNING:tensorflow:From /Users/seungmin/Projects/OpenVINO/tensorflow-yolo-v3/utils.py:56: The name tf.gfile.GFile is deprecated. Please use tf.io.gfile.GFile instead.\n",
      "\n",
      "W0925 10:35:49.988224 4643411392 deprecation_wrapper.py:119] From /Users/seungmin/Projects/OpenVINO/tensorflow-yolo-v3/utils.py:56: The name tf.gfile.GFile is deprecated. Please use tf.io.gfile.GFile instead.\n",
      "\n",
      "1186 ops written to frozen_darknet_yolov3_model.pb.\n"
     ]
    }
   ],
   "source": [
    "#Run a converter for Yolov3\n",
    "!python convert_weights_pb.py --class_names coco.names --data_format NHWC --weights_file yolov3.weights"
   ]
  },
  {
   "cell_type": "code",
   "execution_count": 19,
   "metadata": {},
   "outputs": [
    {
     "name": "stdout",
     "output_type": "stream",
     "text": [
      "Model Optimizer arguments:\n",
      "Common parameters:\n",
      "\t- Path to the Input Model: \t/Users/seungmin/Projects/OpenVINO/tensorflow-yolo-v3/frozen_darknet_yolov3_model.pb\n",
      "\t- Path for generated IR: \t/Users/seungmin/Projects/OpenVINO/tensorflow-yolo-v3/.\n",
      "\t- IR output name: \tfrozen_darknet_yolov3_model\n",
      "\t- Log level: \tERROR\n",
      "\t- Batch: \tNot specified, inherited from the model\n",
      "\t- Input layers: \tNot specified, inherited from the model\n",
      "\t- Output layers: \tNot specified, inherited from the model\n",
      "\t- Input shapes: \t[1,416,416,3]\n",
      "\t- Mean values: \tNot specified\n",
      "\t- Scale values: \tNot specified\n",
      "\t- Scale factor: \tNot specified\n",
      "\t- Precision of IR: \tFP32\n",
      "\t- Enable fusing: \tTrue\n",
      "\t- Enable grouped convolutions fusing: \tTrue\n",
      "\t- Move mean values to preprocess section: \tFalse\n",
      "\t- Reverse input channels: \tFalse\n",
      "TensorFlow specific parameters:\n",
      "\t- Input model in text protobuf format: \tFalse\n",
      "\t- Path to model dump for TensorBoard: \tNone\n",
      "\t- List of shared libraries with TensorFlow custom layers implementation: \tNone\n",
      "\t- Update the configuration file with input/output node names: \tNone\n",
      "\t- Use configuration file used to generate the model with Object Detection API: \tNone\n",
      "\t- Operations to offload: \tNone\n",
      "\t- Patterns to offload: \tNone\n",
      "\t- Use the config file: \t/Users/seungmin/Projects/OpenVINO/tensorflow-yolo-v3/../yolo_v3.json\n",
      "Model Optimizer version: \t2019.2.0-436-gf5827d4\n",
      "\n",
      "[ SUCCESS ] Generated IR model.\n",
      "[ SUCCESS ] XML file: /Users/seungmin/Projects/OpenVINO/tensorflow-yolo-v3/./frozen_darknet_yolov3_model.xml\n",
      "[ SUCCESS ] BIN file: /Users/seungmin/Projects/OpenVINO/tensorflow-yolo-v3/./frozen_darknet_yolov3_model.bin\n",
      "[ SUCCESS ] Total execution time: 33.58 seconds. \n"
     ]
    }
   ],
   "source": [
    "#Convert Yolov3 tf model to the IR for CPU\n",
    "!python '/opt/intel/openvino_2019.3.376/deployment_tools/model_optimizer/mo_tf.py' \\\n",
    "--input_model frozen_darknet_yolov3_model.pb \\\n",
    "--tensorflow_use_custom_operations_config ../yolo_v3.json \\\n",
    "--input_shape [1,416,416,3]"
   ]
  },
  {
   "cell_type": "code",
   "execution_count": 2,
   "metadata": {},
   "outputs": [
    {
     "name": "stdout",
     "output_type": "stream",
     "text": [
      "Model Optimizer arguments:\n",
      "Common parameters:\n",
      "\t- Path to the Input Model: \t/Users/seungmin/Projects/OpenVINO/tensorflow-yolo-v3/frozen_darknet_yolov3_model.pb\n",
      "\t- Path for generated IR: \t/Users/seungmin/Projects/OpenVINO/tensorflow-yolo-v3/.\n",
      "\t- IR output name: \tfrozen_darknet_yolov3_model_fp16\n",
      "\t- Log level: \tERROR\n",
      "\t- Batch: \tNot specified, inherited from the model\n",
      "\t- Input layers: \tNot specified, inherited from the model\n",
      "\t- Output layers: \tNot specified, inherited from the model\n",
      "\t- Input shapes: \t[1,416,416,3]\n",
      "\t- Mean values: \tNot specified\n",
      "\t- Scale values: \tNot specified\n",
      "\t- Scale factor: \tNot specified\n",
      "\t- Precision of IR: \tFP16\n",
      "\t- Enable fusing: \tTrue\n",
      "\t- Enable grouped convolutions fusing: \tTrue\n",
      "\t- Move mean values to preprocess section: \tFalse\n",
      "\t- Reverse input channels: \tFalse\n",
      "TensorFlow specific parameters:\n",
      "\t- Input model in text protobuf format: \tFalse\n",
      "\t- Path to model dump for TensorBoard: \tNone\n",
      "\t- List of shared libraries with TensorFlow custom layers implementation: \tNone\n",
      "\t- Update the configuration file with input/output node names: \tNone\n",
      "\t- Use configuration file used to generate the model with Object Detection API: \tNone\n",
      "\t- Operations to offload: \tNone\n",
      "\t- Patterns to offload: \tNone\n",
      "\t- Use the config file: \t/Users/seungmin/Projects/OpenVINO/tensorflow-yolo-v3/../yolo_v3.json\n",
      "Model Optimizer version: \t2019.2.0-436-gf5827d4\n",
      "\n",
      "[ SUCCESS ] Generated IR model.\n",
      "[ SUCCESS ] XML file: /Users/seungmin/Projects/OpenVINO/tensorflow-yolo-v3/./frozen_darknet_yolov3_model_fp16.xml\n",
      "[ SUCCESS ] BIN file: /Users/seungmin/Projects/OpenVINO/tensorflow-yolo-v3/./frozen_darknet_yolov3_model_fp16.bin\n",
      "[ SUCCESS ] Total execution time: 29.73 seconds. \n"
     ]
    }
   ],
   "source": [
    "#Convert Yolov3 tf model to the IR for GPU/VPU\n",
    "!python '/opt/intel/openvino_2019.3.376/deployment_tools/model_optimizer/mo_tf.py' \\\n",
    "--input_model frozen_darknet_yolov3_model.pb \\\n",
    "--tensorflow_use_custom_operations_config ../yolo_v3.json \\\n",
    "--input_shape [1,416,416,3] \\\n",
    "--data_type=FP16 \\\n",
    "--model_name frozen_darknet_yolov3_model_fp16"
   ]
  },
  {
   "cell_type": "code",
   "execution_count": 74,
   "metadata": {},
   "outputs": [
    {
     "name": "stdout",
     "output_type": "stream",
     "text": [
      "\n",
      "Setting environment variables for building demos...\n",
      "[setupvars.sh] OpenVINO environment initialized\n",
      "-- The C compiler identification is AppleClang 10.0.1.10010046\n",
      "-- The CXX compiler identification is AppleClang 10.0.1.10010046\n",
      "-- Check for working C compiler: /Library/Developer/CommandLineTools/usr/bin/cc\n",
      "-- Check for working C compiler: /Library/Developer/CommandLineTools/usr/bin/cc -- works\n",
      "-- Detecting C compiler ABI info\n",
      "-- Detecting C compiler ABI info - done\n",
      "-- Detecting C compile features\n",
      "-- Detecting C compile features - done\n",
      "-- Check for working CXX compiler: /Library/Developer/CommandLineTools/usr/bin/c++\n",
      "-- Check for working CXX compiler: /Library/Developer/CommandLineTools/usr/bin/c++ -- works\n",
      "-- Detecting CXX compiler ABI info\n",
      "-- Detecting CXX compiler ABI info - done\n",
      "-- Detecting CXX compile features\n",
      "-- Detecting CXX compile features - done\n",
      "-- Looking for C++ include unistd.h\n",
      "-- Looking for C++ include unistd.h - found\n",
      "-- Looking for C++ include stdint.h\n",
      "-- Looking for C++ include stdint.h - found\n",
      "-- Looking for C++ include sys/types.h\n",
      "-- Looking for C++ include sys/types.h - found\n",
      "-- Looking for C++ include fnmatch.h\n",
      "-- Looking for C++ include fnmatch.h - found\n",
      "-- Looking for C++ include stddef.h\n",
      "-- Looking for C++ include stddef.h - found\n",
      "-- Check size of uint32_t\n",
      "-- Check size of uint32_t - done\n",
      "-- Looking for strtoll\n",
      "-- Looking for strtoll - found\n",
      "-- Found InferenceEngine: /opt/intel/openvino_2019.2.275/deployment_tools/inference_engine/lib/intel64/libinference_engine.dylib (Required is at least version \"2.0\") \n",
      "-- Performing Test HAVE_CPUID_INFO\n",
      "-- Performing Test HAVE_CPUID_INFO - Failed\n",
      "-- TBB include: /opt/intel/openvino_2019.2.275/deployment_tools/inference_engine/external/tbb/include\n",
      "-- TBB Release lib: /opt/intel/openvino_2019.2.275/deployment_tools/inference_engine/external/tbb/lib/libtbb.dylib\n",
      "-- TBB Debug lib: /opt/intel/openvino_2019.2.275/deployment_tools/inference_engine/external/tbb/lib/libtbb_debug.dylib\n",
      "-- Looking for pthread.h\n",
      "-- Looking for pthread.h - found\n",
      "-- Performing Test CMAKE_HAVE_LIBC_PTHREAD\n",
      "-- Performing Test CMAKE_HAVE_LIBC_PTHREAD - Success\n",
      "-- Found Threads: TRUE  \n",
      "-- Configuring done\n",
      "CMake Warning (dev):\n",
      "  Policy CMP0042 is not set: MACOSX_RPATH is enabled by default.  Run \"cmake\n",
      "  --help-policy CMP0042\" for policy details.  Use the cmake_policy command to\n",
      "  set the policy and suppress this warning.\n",
      "\n",
      "  MACOSX_RPATH is not specified for the following targets:\n",
      "\n",
      "   format_reader\n",
      "   ie_cpu_extension\n",
      "\n",
      "This warning is for project developers.  Use -Wno-dev to suppress it.\n",
      "\n",
      "-- Generating done\n",
      "-- Build files have been written to: /Users/seungmin/omz_demos_build\n",
      "[  3%] Built target gflags_nothreads_static\n",
      "[  7%] Built target format_reader\n",
      "[ 40%] Built target ie_cpu_extension\n",
      "[ 41%] Built target mask_rcnn_demo\n",
      "[ 46%] Built target text_detection_demo\n",
      "[ 50%] Built target interactive_face_detection_demo\n",
      "[ 51%] Built target crossroad_camera_demo\n",
      "[ 56%] Built target common\n",
      "[ 61%] Built target human_pose_estimation_demo\n",
      "[ 62%] Built target object_detection_demo_faster_rcnn\n",
      "[ 63%] Built target object_detection_demo_yolov3_async\n",
      "[ 71%] Built target pedestrian_tracker_demo\n",
      "[ 74%] Built target security_barrier_camera_demo\n",
      "[ 74%] Built target object_detection_demo_ssd_async\n",
      "[ 77%] Built target segmentation_demo\n",
      "[ 78%] Built target multi-channel-face-detection-demo\n",
      "[ 86%] Built target gaze_estimation_demo\n",
      "[ 88%] Built target super_resolution_demo\n",
      "[ 93%] Built target multi-channel-human-pose-estimation-demo\n",
      "[100%] Built target smart_classroom_demo\n",
      "[100%] Built target ie_samples\n",
      "\n",
      "Build completed, you can find binaries for all demos in the /Users/seungmin/omz_demos_build/intel64/Release subfolder.\n",
      "\n"
     ]
    }
   ],
   "source": [
    "# go to the right directory, build demos\n",
    "!./build_demos.sh"
   ]
  },
  {
   "cell_type": "code",
   "execution_count": 89,
   "metadata": {},
   "outputs": [
    {
     "name": "stdout",
     "output_type": "stream",
     "text": [
      "InferenceEngine: \n",
      "\tAPI version ............ 2.0\n",
      "\tBuild .................. 27579\n",
      "\tDescription ....... API\n",
      "\n",
      "object_detection_demo_yolov3_async [OPTION]\n",
      "Options:\n",
      "\n",
      "    -h                        Print a usage message.\n",
      "    -i \"<path>\"               Required. Path to a video file (specify \"cam\" to work with camera).\n",
      "    -m \"<path>\"               Required. Path to an .xml file with a trained model.\n",
      "      -l \"<absolute_path>\"    Optional. Required for CPU custom layers. Absolute path to a shared library with the layers implementation.\n",
      "          Or\n",
      "      -c \"<absolute_path>\"    Optional. Required for GPU custom kernels. Absolute path to the .xml file with the kernels description.\n",
      "    -d \"<device>\"             Optional. Specify a target device to infer on (the list of available devices is shown below). Default value is CPU. The demo will look for a suitable plugin for the specified device\n",
      "    -pc                       Optional. Enable per-layer performance report.\n",
      "    -r                        Optional. Output inference results raw values showing.\n",
      "    -t                        Optional. Probability threshold for detections.\n",
      "    -iou_t                    Optional. Filtering intersection over union threshold for overlapping boxes.\n",
      "    -auto_resize              Optional. Enable resizable input with support of ROI crop and auto resize.\n",
      "\n",
      "Available target devices:  HDDL\n"
     ]
    }
   ],
   "source": [
    "# Check the options present in Yolov3 sample from built inference engine samples\n",
    "!\"/Users/...../omz_demos_build/intel64/Release/object_detection_demo_yolov3_async\" -h"
   ]
  },
  {
   "cell_type": "code",
   "execution_count": 94,
   "metadata": {},
   "outputs": [
    {
     "name": "stdout",
     "output_type": "stream",
     "text": [
      "[setupvars.sh] OpenVINO environment initialized\r\n"
     ]
    }
   ],
   "source": [
    "!source /opt/intel/openvino_2019.3.376/bin/setupvars.sh"
   ]
  },
  {
   "cell_type": "code",
   "execution_count": 95,
   "metadata": {},
   "outputs": [
    {
     "name": "stdout",
     "output_type": "stream",
     "text": [
      "InferenceEngine: \n",
      "\tAPI version ............ 2.0\n",
      "\tBuild .................. 27579\n",
      "\tDescription ....... API\n",
      "[ INFO ] Parsing input parameters\n",
      "[ INFO ] Reading input\n",
      "[ INFO ] Loading Inference Engine\n",
      "[ INFO ] Device info: \n",
      "[ ERROR ] Failed to create plugin /opt/intel/openvino_2019.2.275/deployment_tools/inference_engine/lib/intel64/libMKLDNNPlugin.dylib for device CPU\n",
      "Please, check your environment\n",
      "Cannot load library '/opt/intel/openvino_2019.2.275/deployment_tools/inference_engine/lib/intel64/libMKLDNNPlugin.dylib': dlopen(/opt/intel/openvino_2019.2.275/deployment_tools/inference_engine/lib/intel64/libMKLDNNPlugin.dylib, 1): Library not loaded: @rpath/libmkl_tiny_tbb.dylib\n",
      "  Referenced from: /opt/intel/openvino_2019.2.275/deployment_tools/inference_engine/lib/intel64/libMKLDNNPlugin.dylib\n",
      "  Reason: image not found\n",
      "\n"
     ]
    }
   ],
   "source": [
    "# Run\n",
    "\n",
    "!\"/Users/...../omz_demos_build/intel64/Release/object_detection_demo_yolov3_async\" \\\n",
    "-i inputVideo.mp4 \\\n",
    "-m frozen_darknet_yolov3_model.xml \\\n",
    "-d CPU"
   ]
  },
  {
   "cell_type": "code",
   "execution_count": null,
   "metadata": {},
   "outputs": [],
   "source": [
    "!\"/Users/...../omz_demos_build/intel64/Release/object_detection_demo_yolov3_async\" \\\n",
    "-i inputVideo.mp4 \\\n",
    "-m frozen_darknet_yolov3_model_fp16.xml \\\n",
    "-d GPU"
   ]
  }
 ],
 "metadata": {
  "kernelspec": {
   "display_name": "Python 3",
   "language": "python",
   "name": "python3"
  },
  "language_info": {
   "codemirror_mode": {
    "name": "ipython",
    "version": 3
   },
   "file_extension": ".py",
   "mimetype": "text/x-python",
   "name": "python",
   "nbconvert_exporter": "python",
   "pygments_lexer": "ipython3",
   "version": "3.7.4"
  }
 },
 "nbformat": 4,
 "nbformat_minor": 2
}
